/*      */ package thaumcraft.common.lib.world.objects;
/*      */ 
/*      */ import java.util.Random;
/*      */ import net.minecraft.block.Block;
/*      */ import net.minecraft.block.BlockChest;
/*      */ import net.minecraft.block.BlockGrass;
/*      */ import net.minecraft.block.BlockTallGrass;
/*      */ import net.minecraft.block.state.IBlockState;
/*      */ import net.minecraft.init.Blocks;
/*      */ import net.minecraft.tileentity.MobSpawnerBaseLogic;
/*      */ import net.minecraft.tileentity.TileEntityChest;
/*      */ import net.minecraft.tileentity.TileEntityMobSpawner;
/*      */ import net.minecraft.util.BlockPos;
/*      */ import net.minecraft.util.WeightedRandomChestContent;
/*      */ import net.minecraft.world.World;
/*      */ import net.minecraft.world.gen.feature.WorldGenerator;
/*      */ import net.minecraftforge.common.ChestGenHooks;
/*      */ import thaumcraft.api.blocks.BlocksTC;
/*      */ 
/*      */ public class WorldGenMound extends WorldGenerator
/*      */ {
/*      */   protected Block[] GetValidSpawnBlocks()
/*      */   {
/*   24 */     return new Block[] { Blocks.stone, Blocks.grass, Blocks.dirt };
/*      */   }
/*      */   
/*      */ 
/*      */ 
/*      */ 
/*      */   public boolean LocationIsValidSpawn(World world, BlockPos pos)
/*      */   {
/*   32 */     int distanceToAir = 0;
/*      */     
/*   34 */     while ((!world.isAirBlock(pos.up(distanceToAir))) && (distanceToAir < 3)) {
/*   35 */       distanceToAir++;
/*      */     }
/*      */     
/*   38 */     if (distanceToAir > 2) {
/*   39 */       return false;
/*      */     }
/*      */     
/*   42 */     BlockPos pos2 = pos.up(distanceToAir - 1);
/*   43 */     Block blockID = world.getBlockState(pos2).getBlock();
/*   44 */     Block blockIDBelow = world.getBlockState(pos2.down()).getBlock();
/*   45 */     for (Block x : GetValidSpawnBlocks()) {
/*   46 */       if (!world.isAirBlock(pos2.up())) {
/*   47 */         return false;
/*      */       }
/*   49 */       if (blockID == x)
/*   50 */         return true;
/*   51 */       if (((blockID == Blocks.snow_layer) || (blockID == Blocks.tallgrass)) && (blockIDBelow == x)) {
/*   52 */         return true;
/*      */       }
/*      */     }
/*   55 */     return false;
/*      */   }
/*      */   
/*      */   public boolean generate(World world, Random rand, BlockPos pos)
/*      */   {
/*   60 */     int i = pos.getX();
/*   61 */     int j = pos.getY();
/*   62 */     int k = pos.getZ();
/*      */     
/*   64 */     if ((!LocationIsValidSpawn(world, new BlockPos(i + 9, j + 9, k + 9))) || (!LocationIsValidSpawn(world, new BlockPos(i, j + 9, k))) || (!LocationIsValidSpawn(world, new BlockPos(i + 18, j + 9, k))) || (!LocationIsValidSpawn(world, new BlockPos(i + 18, j + 9, k + 18))) || (!LocationIsValidSpawn(world, new BlockPos(i, j + 9, k + 18))))
/*      */     {
/*      */ 
/*      */ 
/*      */ 
/*      */ 
/*      */ 
/*   71 */       return false;
/*      */     }
/*      */     
/*   74 */     world.setBlockState(new BlockPos(i + 0, j + 8, k + 4), Blocks.dirt.getDefaultState());
/*   75 */     world.setBlockState(new BlockPos(i + 0, j + 8, k + 5), Blocks.dirt.getDefaultState());
/*   76 */     world.setBlockState(new BlockPos(i + 0, j + 8, k + 6), Blocks.dirt.getDefaultState());
/*   77 */     world.setBlockState(new BlockPos(i + 0, j + 8, k + 7), Blocks.dirt.getDefaultState());
/*   78 */     world.setBlockState(new BlockPos(i + 0, j + 8, k + 8), Blocks.cobblestone.getDefaultState());
/*   79 */     world.setBlockState(new BlockPos(i + 0, j + 8, k + 9), Blocks.cobblestone.getDefaultState());
/*   80 */     world.setBlockState(new BlockPos(i + 0, j + 8, k + 10), Blocks.cobblestone.getDefaultState());
/*   81 */     world.setBlockState(new BlockPos(i + 0, j + 8, k + 11), Blocks.dirt.getDefaultState());
/*   82 */     world.setBlockState(new BlockPos(i + 0, j + 8, k + 12), Blocks.dirt.getDefaultState());
/*   83 */     world.setBlockState(new BlockPos(i + 0, j + 8, k + 13), Blocks.dirt.getDefaultState());
/*   84 */     world.setBlockState(new BlockPos(i + 0, j + 8, k + 14), Blocks.dirt.getDefaultState());
/*   85 */     world.setBlockState(new BlockPos(i + 0, j + 9, k + 4), Blocks.grass.getDefaultState());
/*   86 */     world.setBlockState(new BlockPos(i + 0, j + 9, k + 5), Blocks.grass.getDefaultState());
/*   87 */     world.setBlockState(new BlockPos(i + 0, j + 9, k + 6), Blocks.grass.getDefaultState());
/*   88 */     world.setBlockState(new BlockPos(i + 0, j + 9, k + 7), Blocks.grass.getDefaultState());
/*   89 */     world.setBlockState(new BlockPos(i + 0, j + 9, k + 8), Blocks.stone_stairs.getStateFromMeta(0));
/*   90 */     world.setBlockState(new BlockPos(i + 0, j + 9, k + 9), Blocks.air.getDefaultState());
/*   91 */     world.setBlockState(new BlockPos(i + 0, j + 9, k + 10), Blocks.stone_stairs.getStateFromMeta(0));
/*   92 */     world.setBlockState(new BlockPos(i + 0, j + 9, k + 11), Blocks.grass.getDefaultState());
/*   93 */     world.setBlockState(new BlockPos(i + 0, j + 9, k + 12), Blocks.grass.getDefaultState());
/*   94 */     world.setBlockState(new BlockPos(i + 0, j + 9, k + 13), Blocks.grass.getDefaultState());
/*   95 */     world.setBlockState(new BlockPos(i + 0, j + 9, k + 14), Blocks.grass.getDefaultState());
/*   96 */     world.setBlockState(new BlockPos(i + 0, j + 10, k + 8), Blocks.air.getDefaultState());
/*   97 */     world.setBlockState(new BlockPos(i + 0, j + 10, k + 9), Blocks.air.getDefaultState());
/*   98 */     world.setBlockState(new BlockPos(i + 0, j + 10, k + 10), Blocks.air.getDefaultState());
/*   99 */     world.setBlockState(new BlockPos(i + 1, j + 8, k + 3), Blocks.dirt.getDefaultState());
/*  100 */     world.setBlockState(new BlockPos(i + 1, j + 8, k + 4), Blocks.dirt.getDefaultState());
/*  101 */     world.setBlockState(new BlockPos(i + 1, j + 8, k + 5), Blocks.dirt.getDefaultState());
/*  102 */     world.setBlockState(new BlockPos(i + 1, j + 8, k + 6), Blocks.dirt.getDefaultState());
/*  103 */     world.setBlockState(new BlockPos(i + 1, j + 8, k + 7), Blocks.dirt.getDefaultState());
/*  104 */     world.setBlockState(new BlockPos(i + 1, j + 8, k + 8), Blocks.cobblestone.getDefaultState());
/*  105 */     world.setBlockState(new BlockPos(i + 1, j + 8, k + 9), Blocks.cobblestone.getDefaultState());
/*  106 */     world.setBlockState(new BlockPos(i + 1, j + 8, k + 10), Blocks.cobblestone.getDefaultState());
/*  107 */     world.setBlockState(new BlockPos(i + 1, j + 8, k + 11), Blocks.dirt.getDefaultState());
/*  108 */     world.setBlockState(new BlockPos(i + 1, j + 8, k + 12), Blocks.dirt.getDefaultState());
/*  109 */     world.setBlockState(new BlockPos(i + 1, j + 8, k + 13), Blocks.dirt.getDefaultState());
/*  110 */     world.setBlockState(new BlockPos(i + 1, j + 8, k + 14), Blocks.dirt.getDefaultState());
/*  111 */     world.setBlockState(new BlockPos(i + 1, j + 8, k + 15), Blocks.dirt.getDefaultState());
/*  112 */     world.setBlockState(new BlockPos(i + 1, j + 9, k + 3), Blocks.grass.getDefaultState());
/*  113 */     world.setBlockState(new BlockPos(i + 1, j + 9, k + 4), Blocks.dirt.getDefaultState());
/*  114 */     world.setBlockState(new BlockPos(i + 1, j + 9, k + 5), Blocks.dirt.getDefaultState());
/*  115 */     world.setBlockState(new BlockPos(i + 1, j + 9, k + 6), Blocks.dirt.getDefaultState());
/*  116 */     world.setBlockState(new BlockPos(i + 1, j + 9, k + 7), Blocks.dirt.getDefaultState());
/*  117 */     world.setBlockState(new BlockPos(i + 1, j + 9, k + 8), Blocks.cobblestone.getDefaultState());
/*  118 */     world.setBlockState(new BlockPos(i + 1, j + 9, k + 9), Blocks.air.getDefaultState());
/*  119 */     world.setBlockState(new BlockPos(i + 1, j + 9, k + 10), Blocks.cobblestone.getDefaultState());
/*  120 */     world.setBlockState(new BlockPos(i + 1, j + 9, k + 11), Blocks.dirt.getDefaultState());
/*  121 */     world.setBlockState(new BlockPos(i + 1, j + 9, k + 12), Blocks.dirt.getDefaultState());
/*  122 */     world.setBlockState(new BlockPos(i + 1, j + 9, k + 13), Blocks.dirt.getDefaultState());
/*  123 */     world.setBlockState(new BlockPos(i + 1, j + 9, k + 14), Blocks.dirt.getDefaultState());
/*  124 */     world.setBlockState(new BlockPos(i + 1, j + 9, k + 15), Blocks.grass.getDefaultState());
/*  125 */     world.setBlockState(new BlockPos(i + 1, j + 10, k + 4), Blocks.grass.getDefaultState());
/*  126 */     world.setBlockState(new BlockPos(i + 1, j + 10, k + 5), Blocks.grass.getDefaultState());
/*  127 */     world.setBlockState(new BlockPos(i + 1, j + 10, k + 6), Blocks.dirt.getDefaultState());
/*  128 */     world.setBlockState(new BlockPos(i + 1, j + 10, k + 7), Blocks.dirt.getDefaultState());
/*  129 */     world.setBlockState(new BlockPos(i + 1, j + 10, k + 8), Blocks.stone_stairs.getStateFromMeta(0));
/*  130 */     world.setBlockState(new BlockPos(i + 1, j + 10, k + 9), Blocks.air.getDefaultState());
/*  131 */     world.setBlockState(new BlockPos(i + 1, j + 10, k + 10), Blocks.stone_stairs.getStateFromMeta(0));
/*  132 */     world.setBlockState(new BlockPos(i + 1, j + 10, k + 11), Blocks.grass.getDefaultState());
/*  133 */     world.setBlockState(new BlockPos(i + 1, j + 10, k + 12), Blocks.grass.getDefaultState());
/*  134 */     world.setBlockState(new BlockPos(i + 1, j + 10, k + 13), Blocks.grass.getDefaultState());
/*  135 */     world.setBlockState(new BlockPos(i + 1, j + 10, k + 14), Blocks.grass.getDefaultState());
/*  136 */     world.setBlockState(new BlockPos(i + 1, j + 11, k + 6), Blocks.grass.getDefaultState());
/*  137 */     world.setBlockState(new BlockPos(i + 1, j + 11, k + 7), Blocks.grass.getDefaultState());
/*  138 */     world.setBlockState(new BlockPos(i + 1, j + 11, k + 8), Blocks.air.getDefaultState());
/*  139 */     world.setBlockState(new BlockPos(i + 1, j + 11, k + 9), Blocks.air.getDefaultState());
/*  140 */     world.setBlockState(new BlockPos(i + 1, j + 11, k + 10), Blocks.air.getDefaultState());
/*  141 */     world.setBlockState(new BlockPos(i + 2, j + 8, k + 2), Blocks.dirt.getDefaultState());
/*  142 */     world.setBlockState(new BlockPos(i + 2, j + 8, k + 3), Blocks.dirt.getDefaultState());
/*  143 */     world.setBlockState(new BlockPos(i + 2, j + 8, k + 4), Blocks.dirt.getDefaultState());
/*  144 */     world.setBlockState(new BlockPos(i + 2, j + 8, k + 5), Blocks.dirt.getDefaultState());
/*  145 */     world.setBlockState(new BlockPos(i + 2, j + 8, k + 6), Blocks.dirt.getDefaultState());
/*  146 */     world.setBlockState(new BlockPos(i + 2, j + 8, k + 7), Blocks.cobblestone.getDefaultState());
/*  147 */     world.setBlockState(new BlockPos(i + 2, j + 8, k + 8), Blocks.cobblestone.getDefaultState());
/*  148 */     world.setBlockState(new BlockPos(i + 2, j + 8, k + 9), Blocks.mossy_cobblestone.getDefaultState());
/*  149 */     world.setBlockState(new BlockPos(i + 2, j + 8, k + 10), Blocks.cobblestone.getDefaultState());
/*  150 */     world.setBlockState(new BlockPos(i + 2, j + 8, k + 11), Blocks.cobblestone.getDefaultState());
/*  151 */     world.setBlockState(new BlockPos(i + 2, j + 8, k + 12), Blocks.dirt.getDefaultState());
/*  152 */     world.setBlockState(new BlockPos(i + 2, j + 8, k + 13), Blocks.dirt.getDefaultState());
/*  153 */     world.setBlockState(new BlockPos(i + 2, j + 8, k + 14), Blocks.dirt.getDefaultState());
/*  154 */     world.setBlockState(new BlockPos(i + 2, j + 8, k + 15), Blocks.dirt.getDefaultState());
/*  155 */     world.setBlockState(new BlockPos(i + 2, j + 8, k + 16), Blocks.dirt.getDefaultState());
/*  156 */     world.setBlockState(new BlockPos(i + 2, j + 9, k + 2), Blocks.grass.getDefaultState());
/*  157 */     world.setBlockState(new BlockPos(i + 2, j + 9, k + 3), Blocks.dirt.getDefaultState());
/*  158 */     world.setBlockState(new BlockPos(i + 2, j + 9, k + 4), Blocks.dirt.getDefaultState());
/*  159 */     world.setBlockState(new BlockPos(i + 2, j + 9, k + 5), Blocks.dirt.getDefaultState());
/*  160 */     world.setBlockState(new BlockPos(i + 2, j + 9, k + 6), Blocks.dirt.getDefaultState());
/*  161 */     world.setBlockState(new BlockPos(i + 2, j + 9, k + 7), Blocks.dirt.getDefaultState());
/*  162 */     world.setBlockState(new BlockPos(i + 2, j + 9, k + 8), Blocks.cobblestone.getDefaultState());
/*  163 */     world.setBlockState(new BlockPos(i + 2, j + 9, k + 9), Blocks.air.getDefaultState());
/*  164 */     world.setBlockState(new BlockPos(i + 2, j + 9, k + 10), Blocks.cobblestone.getDefaultState());
/*  165 */     world.setBlockState(new BlockPos(i + 2, j + 9, k + 11), Blocks.dirt.getDefaultState());
/*  166 */     world.setBlockState(new BlockPos(i + 2, j + 9, k + 12), Blocks.dirt.getDefaultState());
/*  167 */     world.setBlockState(new BlockPos(i + 2, j + 9, k + 13), Blocks.dirt.getDefaultState());
/*  168 */     world.setBlockState(new BlockPos(i + 2, j + 9, k + 14), Blocks.dirt.getDefaultState());
/*  169 */     world.setBlockState(new BlockPos(i + 2, j + 9, k + 15), Blocks.dirt.getDefaultState());
/*  170 */     world.setBlockState(new BlockPos(i + 2, j + 9, k + 16), Blocks.grass.getDefaultState());
/*  171 */     world.setBlockState(new BlockPos(i + 2, j + 10, k + 3), Blocks.grass.getDefaultState());
/*  172 */     world.setBlockState(new BlockPos(i + 2, j + 10, k + 4), Blocks.dirt.getDefaultState());
/*  173 */     world.setBlockState(new BlockPos(i + 2, j + 10, k + 5), Blocks.dirt.getDefaultState());
/*  174 */     world.setBlockState(new BlockPos(i + 2, j + 10, k + 6), Blocks.dirt.getDefaultState());
/*  175 */     world.setBlockState(new BlockPos(i + 2, j + 10, k + 7), Blocks.dirt.getDefaultState());
/*  176 */     world.setBlockState(new BlockPos(i + 2, j + 10, k + 8), Blocks.cobblestone.getDefaultState());
/*  177 */     world.setBlockState(new BlockPos(i + 2, j + 10, k + 9), Blocks.air.getDefaultState());
/*  178 */     world.setBlockState(new BlockPos(i + 2, j + 10, k + 10), Blocks.mossy_cobblestone.getDefaultState());
/*  179 */     world.setBlockState(new BlockPos(i + 2, j + 10, k + 11), Blocks.dirt.getDefaultState());
/*  180 */     world.setBlockState(new BlockPos(i + 2, j + 10, k + 12), Blocks.dirt.getDefaultState());
/*  181 */     world.setBlockState(new BlockPos(i + 2, j + 10, k + 13), Blocks.dirt.getDefaultState());
/*  182 */     world.setBlockState(new BlockPos(i + 2, j + 10, k + 14), Blocks.dirt.getDefaultState());
/*  183 */     world.setBlockState(new BlockPos(i + 2, j + 10, k + 15), Blocks.grass.getDefaultState());
/*  184 */     world.setBlockState(new BlockPos(i + 2, j + 11, k + 4), Blocks.grass.getDefaultState());
/*  185 */     world.setBlockState(new BlockPos(i + 2, j + 11, k + 5), Blocks.grass.getDefaultState());
/*  186 */     world.setBlockState(new BlockPos(i + 2, j + 11, k + 6), Blocks.dirt.getDefaultState());
/*  187 */     world.setBlockState(new BlockPos(i + 2, j + 11, k + 7), Blocks.dirt.getDefaultState());
/*  188 */     world.setBlockState(new BlockPos(i + 2, j + 11, k + 8), Blocks.cobblestone.getDefaultState());
/*  189 */     world.setBlockState(new BlockPos(i + 2, j + 11, k + 9), Blocks.stonebrick.getStateFromMeta(3));
/*  190 */     world.setBlockState(new BlockPos(i + 2, j + 11, k + 10), Blocks.mossy_cobblestone.getDefaultState());
/*  191 */     world.setBlockState(new BlockPos(i + 2, j + 11, k + 11), Blocks.dirt.getDefaultState());
/*  192 */     world.setBlockState(new BlockPos(i + 2, j + 11, k + 12), Blocks.grass.getDefaultState());
/*  193 */     world.setBlockState(new BlockPos(i + 2, j + 11, k + 13), Blocks.grass.getDefaultState());
/*  194 */     world.setBlockState(new BlockPos(i + 2, j + 11, k + 14), Blocks.grass.getDefaultState());
/*  195 */     world.setBlockState(new BlockPos(i + 2, j + 12, k + 6), Blocks.grass.getDefaultState());
/*  196 */     world.setBlockState(new BlockPos(i + 2, j + 12, k + 7), Blocks.grass.getDefaultState());
/*  197 */     world.setBlockState(new BlockPos(i + 2, j + 12, k + 8), Blocks.grass.getDefaultState());
/*  198 */     world.setBlockState(new BlockPos(i + 2, j + 12, k + 9), Blocks.grass.getDefaultState());
/*  199 */     world.setBlockState(new BlockPos(i + 2, j + 12, k + 10), Blocks.grass.getDefaultState());
/*  200 */     world.setBlockState(new BlockPos(i + 2, j + 12, k + 11), Blocks.grass.getDefaultState());
/*  201 */     world.setBlockState(new BlockPos(i + 3, j + 4, k + 3), Blocks.cobblestone.getDefaultState());
/*  202 */     world.setBlockState(new BlockPos(i + 3, j + 4, k + 4), Blocks.cobblestone.getDefaultState());
/*  203 */     world.setBlockState(new BlockPos(i + 3, j + 4, k + 5), Blocks.cobblestone.getDefaultState());
/*  204 */     world.setBlockState(new BlockPos(i + 3, j + 4, k + 6), Blocks.cobblestone.getDefaultState());
/*  205 */     world.setBlockState(new BlockPos(i + 3, j + 4, k + 7), Blocks.cobblestone.getDefaultState());
/*  206 */     world.setBlockState(new BlockPos(i + 3, j + 4, k + 8), Blocks.cobblestone.getDefaultState());
/*  207 */     world.setBlockState(new BlockPos(i + 3, j + 4, k + 9), Blocks.cobblestone.getDefaultState());
/*  208 */     world.setBlockState(new BlockPos(i + 3, j + 4, k + 10), Blocks.cobblestone.getDefaultState());
/*  209 */     world.setBlockState(new BlockPos(i + 3, j + 4, k + 11), Blocks.cobblestone.getDefaultState());
/*  210 */     world.setBlockState(new BlockPos(i + 3, j + 4, k + 12), Blocks.cobblestone.getDefaultState());
/*  211 */     world.setBlockState(new BlockPos(i + 3, j + 4, k + 13), Blocks.cobblestone.getDefaultState());
/*  212 */     world.setBlockState(new BlockPos(i + 3, j + 4, k + 14), Blocks.cobblestone.getDefaultState());
/*  213 */     world.setBlockState(new BlockPos(i + 3, j + 4, k + 15), Blocks.cobblestone.getDefaultState());
/*  214 */     world.setBlockState(new BlockPos(i + 3, j + 5, k + 3), Blocks.cobblestone.getDefaultState());
/*  215 */     world.setBlockState(new BlockPos(i + 3, j + 5, k + 4), Blocks.cobblestone.getDefaultState());
/*  216 */     world.setBlockState(new BlockPos(i + 3, j + 5, k + 5), Blocks.cobblestone.getDefaultState());
/*  217 */     world.setBlockState(new BlockPos(i + 3, j + 5, k + 6), Blocks.cobblestone.getDefaultState());
/*  218 */     world.setBlockState(new BlockPos(i + 3, j + 5, k + 7), Blocks.mossy_cobblestone.getDefaultState());
/*  219 */     world.setBlockState(new BlockPos(i + 3, j + 5, k + 8), Blocks.mossy_cobblestone.getDefaultState());
/*  220 */     world.setBlockState(new BlockPos(i + 3, j + 5, k + 9), Blocks.cobblestone.getDefaultState());
/*  221 */     world.setBlockState(new BlockPos(i + 3, j + 5, k + 10), Blocks.cobblestone.getDefaultState());
/*  222 */     world.setBlockState(new BlockPos(i + 3, j + 5, k + 11), Blocks.cobblestone.getDefaultState());
/*  223 */     world.setBlockState(new BlockPos(i + 3, j + 5, k + 12), Blocks.cobblestone.getDefaultState());
/*  224 */     world.setBlockState(new BlockPos(i + 3, j + 5, k + 13), Blocks.cobblestone.getDefaultState());
/*  225 */     world.setBlockState(new BlockPos(i + 3, j + 5, k + 14), Blocks.cobblestone.getDefaultState());
/*  226 */     world.setBlockState(new BlockPos(i + 3, j + 5, k + 15), Blocks.cobblestone.getDefaultState());
/*  227 */     world.setBlockState(new BlockPos(i + 3, j + 6, k + 3), Blocks.cobblestone.getDefaultState());
/*  228 */     world.setBlockState(new BlockPos(i + 3, j + 6, k + 4), Blocks.cobblestone.getDefaultState());
/*  229 */     world.setBlockState(new BlockPos(i + 3, j + 6, k + 5), Blocks.cobblestone.getDefaultState());
/*  230 */     world.setBlockState(new BlockPos(i + 3, j + 6, k + 6), Blocks.cobblestone.getDefaultState());
/*  231 */     world.setBlockState(new BlockPos(i + 3, j + 6, k + 7), Blocks.cobblestone.getDefaultState());
/*  232 */     world.setBlockState(new BlockPos(i + 3, j + 6, k + 8), Blocks.cobblestone.getDefaultState());
/*  233 */     world.setBlockState(new BlockPos(i + 3, j + 6, k + 9), Blocks.cobblestone.getDefaultState());
/*  234 */     world.setBlockState(new BlockPos(i + 3, j + 6, k + 10), Blocks.cobblestone.getDefaultState());
/*  235 */     world.setBlockState(new BlockPos(i + 3, j + 6, k + 11), Blocks.cobblestone.getDefaultState());
/*  236 */     world.setBlockState(new BlockPos(i + 3, j + 6, k + 12), Blocks.cobblestone.getDefaultState());
/*  237 */     world.setBlockState(new BlockPos(i + 3, j + 6, k + 13), Blocks.mossy_cobblestone.getDefaultState());
/*  238 */     world.setBlockState(new BlockPos(i + 3, j + 6, k + 14), Blocks.cobblestone.getDefaultState());
/*  239 */     world.setBlockState(new BlockPos(i + 3, j + 6, k + 15), Blocks.cobblestone.getDefaultState());
/*  240 */     world.setBlockState(new BlockPos(i + 3, j + 7, k + 3), Blocks.cobblestone.getDefaultState());
/*  241 */     world.setBlockState(new BlockPos(i + 3, j + 7, k + 4), Blocks.cobblestone.getDefaultState());
/*  242 */     world.setBlockState(new BlockPos(i + 3, j + 7, k + 5), Blocks.cobblestone.getDefaultState());
/*  243 */     world.setBlockState(new BlockPos(i + 3, j + 7, k + 6), Blocks.cobblestone.getDefaultState());
/*  244 */     world.setBlockState(new BlockPos(i + 3, j + 7, k + 7), Blocks.cobblestone.getDefaultState());
/*  245 */     world.setBlockState(new BlockPos(i + 3, j + 7, k + 8), Blocks.cobblestone.getDefaultState());
/*  246 */     world.setBlockState(new BlockPos(i + 3, j + 7, k + 9), Blocks.cobblestone.getDefaultState());
/*  247 */     world.setBlockState(new BlockPos(i + 3, j + 7, k + 10), Blocks.cobblestone.getDefaultState());
/*  248 */     world.setBlockState(new BlockPos(i + 3, j + 7, k + 11), Blocks.mossy_cobblestone.getDefaultState());
/*  249 */     world.setBlockState(new BlockPos(i + 3, j + 7, k + 12), Blocks.cobblestone.getDefaultState());
/*  250 */     world.setBlockState(new BlockPos(i + 3, j + 7, k + 13), Blocks.cobblestone.getDefaultState());
/*  251 */     world.setBlockState(new BlockPos(i + 3, j + 7, k + 14), Blocks.cobblestone.getDefaultState());
/*  252 */     world.setBlockState(new BlockPos(i + 3, j + 7, k + 15), Blocks.cobblestone.getDefaultState());
/*  253 */     world.setBlockState(new BlockPos(i + 3, j + 8, k + 1), Blocks.dirt.getDefaultState());
/*  254 */     world.setBlockState(new BlockPos(i + 3, j + 8, k + 2), Blocks.dirt.getDefaultState());
/*  255 */     world.setBlockState(new BlockPos(i + 3, j + 8, k + 3), Blocks.cobblestone.getDefaultState());
/*  256 */     world.setBlockState(new BlockPos(i + 3, j + 8, k + 4), Blocks.cobblestone.getDefaultState());
/*  257 */     world.setBlockState(new BlockPos(i + 3, j + 8, k + 5), Blocks.cobblestone.getDefaultState());
/*  258 */     world.setBlockState(new BlockPos(i + 3, j + 8, k + 6), Blocks.cobblestone.getDefaultState());
/*  259 */     world.setBlockState(new BlockPos(i + 3, j + 8, k + 7), Blocks.mossy_cobblestone.getDefaultState());
/*  260 */     world.setBlockState(new BlockPos(i + 3, j + 8, k + 8), Blocks.cobblestone.getDefaultState());
/*  261 */     world.setBlockState(new BlockPos(i + 3, j + 8, k + 9), Blocks.cobblestone.getDefaultState());
/*  262 */     world.setBlockState(new BlockPos(i + 3, j + 8, k + 10), Blocks.cobblestone.getDefaultState());
/*  263 */     world.setBlockState(new BlockPos(i + 3, j + 8, k + 11), Blocks.cobblestone.getDefaultState());
/*  264 */     world.setBlockState(new BlockPos(i + 3, j + 8, k + 12), Blocks.cobblestone.getDefaultState());
/*  265 */     world.setBlockState(new BlockPos(i + 3, j + 8, k + 13), Blocks.cobblestone.getDefaultState());
/*  266 */     world.setBlockState(new BlockPos(i + 3, j + 8, k + 14), Blocks.cobblestone.getDefaultState());
/*  267 */     world.setBlockState(new BlockPos(i + 3, j + 8, k + 15), Blocks.cobblestone.getDefaultState());
/*  268 */     world.setBlockState(new BlockPos(i + 3, j + 8, k + 16), Blocks.dirt.getDefaultState());
/*  269 */     world.setBlockState(new BlockPos(i + 3, j + 8, k + 17), Blocks.dirt.getDefaultState());
/*  270 */     world.setBlockState(new BlockPos(i + 3, j + 9, k + 1), Blocks.grass.getDefaultState());
/*  271 */     world.setBlockState(new BlockPos(i + 3, j + 9, k + 2), Blocks.dirt.getDefaultState());
/*  272 */     world.setBlockState(new BlockPos(i + 3, j + 9, k + 3), Blocks.cobblestone.getDefaultState());
/*  273 */     world.setBlockState(new BlockPos(i + 3, j + 9, k + 4), Blocks.cobblestone.getDefaultState());
/*  274 */     world.setBlockState(new BlockPos(i + 3, j + 9, k + 5), Blocks.cobblestone.getDefaultState());
/*  275 */     world.setBlockState(new BlockPos(i + 3, j + 9, k + 6), Blocks.cobblestone.getDefaultState());
/*  276 */     world.setBlockState(new BlockPos(i + 3, j + 9, k + 7), Blocks.cobblestone.getDefaultState());
/*  277 */     world.setBlockState(new BlockPos(i + 3, j + 9, k + 8), Blocks.cobblestone.getDefaultState());
/*  278 */     world.setBlockState(new BlockPos(i + 3, j + 9, k + 9), Blocks.iron_bars.getDefaultState());
/*  279 */     world.setBlockState(new BlockPos(i + 3, j + 9, k + 10), Blocks.cobblestone.getDefaultState());
/*  280 */     world.setBlockState(new BlockPos(i + 3, j + 9, k + 11), Blocks.cobblestone.getDefaultState());
/*  281 */     world.setBlockState(new BlockPos(i + 3, j + 9, k + 12), Blocks.mossy_cobblestone.getDefaultState());
/*  282 */     world.setBlockState(new BlockPos(i + 3, j + 9, k + 13), Blocks.cobblestone.getDefaultState());
/*  283 */     world.setBlockState(new BlockPos(i + 3, j + 9, k + 14), Blocks.cobblestone.getDefaultState());
/*  284 */     world.setBlockState(new BlockPos(i + 3, j + 9, k + 15), Blocks.cobblestone.getDefaultState());
/*  285 */     world.setBlockState(new BlockPos(i + 3, j + 9, k + 16), Blocks.dirt.getDefaultState());
/*  286 */     world.setBlockState(new BlockPos(i + 3, j + 9, k + 17), Blocks.grass.getDefaultState());
/*  287 */     world.setBlockState(new BlockPos(i + 3, j + 10, k + 2), Blocks.grass.getDefaultState());
/*  288 */     world.setBlockState(new BlockPos(i + 3, j + 10, k + 3), Blocks.cobblestone.getDefaultState());
/*  289 */     world.setBlockState(new BlockPos(i + 3, j + 10, k + 4), Blocks.mossy_cobblestone.getDefaultState());
/*  290 */     world.setBlockState(new BlockPos(i + 3, j + 10, k + 5), Blocks.mossy_cobblestone.getDefaultState());
/*  291 */     world.setBlockState(new BlockPos(i + 3, j + 10, k + 6), Blocks.cobblestone.getDefaultState());
/*  292 */     world.setBlockState(new BlockPos(i + 3, j + 10, k + 7), Blocks.mossy_cobblestone.getDefaultState());
/*  293 */     world.setBlockState(new BlockPos(i + 3, j + 10, k + 8), Blocks.cobblestone.getDefaultState());
/*  294 */     world.setBlockState(new BlockPos(i + 3, j + 10, k + 9), Blocks.iron_bars.getDefaultState());
/*  295 */     world.setBlockState(new BlockPos(i + 3, j + 10, k + 10), Blocks.cobblestone.getDefaultState());
/*  296 */     world.setBlockState(new BlockPos(i + 3, j + 10, k + 11), Blocks.cobblestone.getDefaultState());
/*  297 */     world.setBlockState(new BlockPos(i + 3, j + 10, k + 12), Blocks.cobblestone.getDefaultState());
/*  298 */     world.setBlockState(new BlockPos(i + 3, j + 10, k + 13), Blocks.cobblestone.getDefaultState());
/*  299 */     world.setBlockState(new BlockPos(i + 3, j + 10, k + 14), Blocks.cobblestone.getDefaultState());
/*  300 */     world.setBlockState(new BlockPos(i + 3, j + 10, k + 15), Blocks.cobblestone.getDefaultState());
/*  301 */     world.setBlockState(new BlockPos(i + 3, j + 10, k + 16), Blocks.grass.getDefaultState());
/*  302 */     world.setBlockState(new BlockPos(i + 3, j + 11, k + 3), Blocks.grass.getDefaultState());
/*  303 */     world.setBlockState(new BlockPos(i + 3, j + 11, k + 4), Blocks.dirt.getDefaultState());
/*  304 */     world.setBlockState(new BlockPos(i + 3, j + 11, k + 5), Blocks.cobblestone.getDefaultState());
/*  305 */     world.setBlockState(new BlockPos(i + 3, j + 11, k + 6), Blocks.cobblestone.getDefaultState());
/*  306 */     world.setBlockState(new BlockPos(i + 3, j + 11, k + 7), Blocks.cobblestone.getDefaultState());
/*  307 */     world.setBlockState(new BlockPos(i + 3, j + 11, k + 8), Blocks.cobblestone.getDefaultState());
/*  308 */     world.setBlockState(new BlockPos(i + 3, j + 11, k + 9), Blocks.mossy_cobblestone.getDefaultState());
/*  309 */     world.setBlockState(new BlockPos(i + 3, j + 11, k + 10), Blocks.cobblestone.getDefaultState());
/*  310 */     world.setBlockState(new BlockPos(i + 3, j + 11, k + 11), Blocks.cobblestone.getDefaultState());
/*  311 */     world.setBlockState(new BlockPos(i + 3, j + 11, k + 12), Blocks.cobblestone.getDefaultState());
/*  312 */     world.setBlockState(new BlockPos(i + 3, j + 11, k + 13), Blocks.cobblestone.getDefaultState());
/*  313 */     world.setBlockState(new BlockPos(i + 3, j + 11, k + 14), Blocks.dirt.getDefaultState());
/*  314 */     world.setBlockState(new BlockPos(i + 3, j + 11, k + 15), Blocks.grass.getDefaultState());
/*  315 */     world.setBlockState(new BlockPos(i + 3, j + 12, k + 4), Blocks.grass.getDefaultState());
/*  316 */     world.setBlockState(new BlockPos(i + 3, j + 12, k + 5), Blocks.grass.getDefaultState());
/*  317 */     world.setBlockState(new BlockPos(i + 3, j + 12, k + 6), Blocks.grass.getDefaultState());
/*  318 */     world.setBlockState(new BlockPos(i + 3, j + 12, k + 7), Blocks.grass.getDefaultState());
/*  319 */     world.setBlockState(new BlockPos(i + 3, j + 12, k + 8), Blocks.grass.getDefaultState());
/*  320 */     world.setBlockState(new BlockPos(i + 3, j + 12, k + 9), Blocks.grass.getDefaultState());
/*  321 */     world.setBlockState(new BlockPos(i + 3, j + 12, k + 10), Blocks.grass.getDefaultState());
/*  322 */     world.setBlockState(new BlockPos(i + 3, j + 12, k + 11), Blocks.grass.getDefaultState());
/*  323 */     world.setBlockState(new BlockPos(i + 3, j + 12, k + 12), Blocks.grass.getDefaultState());
/*  324 */     world.setBlockState(new BlockPos(i + 3, j + 12, k + 13), Blocks.grass.getDefaultState());
/*  325 */     world.setBlockState(new BlockPos(i + 3, j + 12, k + 14), Blocks.grass.getDefaultState());
/*  326 */     world.setBlockState(new BlockPos(i + 4, j + 4, k + 3), Blocks.cobblestone.getDefaultState());
/*  327 */     world.setBlockState(new BlockPos(i + 4, j + 4, k + 4), Blocks.cobblestone.getDefaultState());
/*  328 */     world.setBlockState(new BlockPos(i + 4, j + 4, k + 5), Blocks.cobblestone.getDefaultState());
/*  329 */     world.setBlockState(new BlockPos(i + 4, j + 4, k + 6), Blocks.cobblestone.getDefaultState());
/*  330 */     world.setBlockState(new BlockPos(i + 4, j + 4, k + 7), Blocks.cobblestone.getDefaultState());
/*  331 */     world.setBlockState(new BlockPos(i + 4, j + 4, k + 8), Blocks.cobblestone.getDefaultState());
/*  332 */     world.setBlockState(new BlockPos(i + 4, j + 4, k + 9), Blocks.cobblestone.getDefaultState());
/*  333 */     world.setBlockState(new BlockPos(i + 4, j + 4, k + 10), Blocks.cobblestone.getDefaultState());
/*  334 */     world.setBlockState(new BlockPos(i + 4, j + 4, k + 11), Blocks.cobblestone.getDefaultState());
/*  335 */     world.setBlockState(new BlockPos(i + 4, j + 4, k + 12), Blocks.cobblestone.getDefaultState());
/*  336 */     world.setBlockState(new BlockPos(i + 4, j + 4, k + 13), Blocks.cobblestone.getDefaultState());
/*  337 */     world.setBlockState(new BlockPos(i + 4, j + 4, k + 14), Blocks.cobblestone.getDefaultState());
/*  338 */     world.setBlockState(new BlockPos(i + 4, j + 4, k + 15), Blocks.cobblestone.getDefaultState());
/*  339 */     world.setBlockState(new BlockPos(i + 4, j + 5, k + 3), Blocks.cobblestone.getDefaultState());
/*      */     
/*  341 */     world.setBlockState(new BlockPos(i + 4, j + 5, k + 15), Blocks.cobblestone.getDefaultState());
/*  342 */     world.setBlockState(new BlockPos(i + 4, j + 6, k + 3), Blocks.cobblestone.getDefaultState());
/*  343 */     world.setBlockState(new BlockPos(i + 4, j + 6, k + 15), Blocks.cobblestone.getDefaultState());
/*  344 */     world.setBlockState(new BlockPos(i + 4, j + 7, k + 3), Blocks.mossy_cobblestone.getDefaultState());
/*  345 */     world.setBlockState(new BlockPos(i + 4, j + 7, k + 15), Blocks.cobblestone.getDefaultState());
/*  346 */     world.setBlockState(new BlockPos(i + 4, j + 8, k + 0), Blocks.dirt.getDefaultState());
/*  347 */     world.setBlockState(new BlockPos(i + 4, j + 8, k + 1), Blocks.dirt.getDefaultState());
/*  348 */     world.setBlockState(new BlockPos(i + 4, j + 8, k + 2), Blocks.dirt.getDefaultState());
/*  349 */     world.setBlockState(new BlockPos(i + 4, j + 8, k + 3), Blocks.cobblestone.getDefaultState());
/*  350 */     world.setBlockState(new BlockPos(i + 4, j + 8, k + 4), Blocks.mossy_cobblestone.getDefaultState());
/*  351 */     world.setBlockState(new BlockPos(i + 4, j + 8, k + 5), Blocks.mossy_cobblestone.getDefaultState());
/*  352 */     world.setBlockState(new BlockPos(i + 4, j + 8, k + 6), Blocks.cobblestone.getDefaultState());
/*  353 */     world.setBlockState(new BlockPos(i + 4, j + 8, k + 7), Blocks.cobblestone.getDefaultState());
/*  354 */     world.setBlockState(new BlockPos(i + 4, j + 8, k + 8), Blocks.cobblestone.getDefaultState());
/*  355 */     world.setBlockState(new BlockPos(i + 4, j + 8, k + 9), Blocks.mossy_cobblestone.getDefaultState());
/*  356 */     world.setBlockState(new BlockPos(i + 4, j + 8, k + 10), Blocks.mossy_cobblestone.getDefaultState());
/*  357 */     world.setBlockState(new BlockPos(i + 4, j + 8, k + 11), Blocks.cobblestone.getDefaultState());
/*  358 */     world.setBlockState(new BlockPos(i + 4, j + 8, k + 12), Blocks.cobblestone.getDefaultState());
/*  359 */     world.setBlockState(new BlockPos(i + 4, j + 8, k + 13), Blocks.cobblestone.getDefaultState());
/*  360 */     world.setBlockState(new BlockPos(i + 4, j + 8, k + 14), Blocks.cobblestone.getDefaultState());
/*  361 */     world.setBlockState(new BlockPos(i + 4, j + 8, k + 15), Blocks.cobblestone.getDefaultState());
/*  362 */     world.setBlockState(new BlockPos(i + 4, j + 8, k + 16), Blocks.dirt.getDefaultState());
/*  363 */     world.setBlockState(new BlockPos(i + 4, j + 8, k + 17), Blocks.dirt.getDefaultState());
/*  364 */     world.setBlockState(new BlockPos(i + 4, j + 8, k + 18), Blocks.dirt.getDefaultState());
/*  365 */     world.setBlockState(new BlockPos(i + 4, j + 9, k + 0), Blocks.grass.getDefaultState());
/*  366 */     world.setBlockState(new BlockPos(i + 4, j + 9, k + 1), Blocks.dirt.getDefaultState());
/*  367 */     world.setBlockState(new BlockPos(i + 4, j + 9, k + 2), Blocks.dirt.getDefaultState());
/*  368 */     world.setBlockState(new BlockPos(i + 4, j + 9, k + 3), Blocks.cobblestone.getDefaultState());
/*  369 */     world.setBlockState(new BlockPos(i + 4, j + 9, k + 15), Blocks.cobblestone.getDefaultState());
/*  370 */     world.setBlockState(new BlockPos(i + 4, j + 9, k + 16), Blocks.dirt.getDefaultState());
/*  371 */     world.setBlockState(new BlockPos(i + 4, j + 9, k + 17), Blocks.dirt.getDefaultState());
/*  372 */     world.setBlockState(new BlockPos(i + 4, j + 9, k + 18), Blocks.grass.getDefaultState());
/*  373 */     world.setBlockState(new BlockPos(i + 4, j + 10, k + 1), Blocks.grass.getDefaultState());
/*  374 */     world.setBlockState(new BlockPos(i + 4, j + 10, k + 2), Blocks.dirt.getDefaultState());
/*  375 */     world.setBlockState(new BlockPos(i + 4, j + 10, k + 3), Blocks.cobblestone.getDefaultState());
/*  376 */     world.setBlockState(new BlockPos(i + 4, j + 10, k + 15), Blocks.mossy_cobblestone.getDefaultState());
/*  377 */     world.setBlockState(new BlockPos(i + 4, j + 10, k + 16), Blocks.dirt.getDefaultState());
/*  378 */     world.setBlockState(new BlockPos(i + 4, j + 10, k + 17), Blocks.grass.getDefaultState());
/*  379 */     world.setBlockState(new BlockPos(i + 4, j + 11, k + 2), Blocks.grass.getDefaultState());
/*  380 */     world.setBlockState(new BlockPos(i + 4, j + 11, k + 3), Blocks.dirt.getDefaultState());
/*  381 */     world.setBlockState(new BlockPos(i + 4, j + 11, k + 4), Blocks.cobblestone.getDefaultState());
/*  382 */     world.setBlockState(new BlockPos(i + 4, j + 11, k + 14), Blocks.mossy_cobblestone.getDefaultState());
/*  383 */     world.setBlockState(new BlockPos(i + 4, j + 11, k + 15), Blocks.dirt.getDefaultState());
/*  384 */     world.setBlockState(new BlockPos(i + 4, j + 11, k + 16), Blocks.grass.getDefaultState());
/*  385 */     world.setBlockState(new BlockPos(i + 4, j + 12, k + 3), Blocks.grass.getDefaultState());
/*  386 */     world.setBlockState(new BlockPos(i + 4, j + 12, k + 4), Blocks.grass.getDefaultState());
/*  387 */     world.setBlockState(new BlockPos(i + 4, j + 12, k + 5), Blocks.cobblestone.getDefaultState());
/*  388 */     world.setBlockState(new BlockPos(i + 4, j + 12, k + 6), Blocks.cobblestone.getDefaultState());
/*  389 */     world.setBlockState(new BlockPos(i + 4, j + 12, k + 7), Blocks.cobblestone.getDefaultState());
/*  390 */     world.setBlockState(new BlockPos(i + 4, j + 12, k + 8), Blocks.cobblestone.getDefaultState());
/*  391 */     world.setBlockState(new BlockPos(i + 4, j + 12, k + 9), Blocks.cobblestone.getDefaultState());
/*  392 */     world.setBlockState(new BlockPos(i + 4, j + 12, k + 10), Blocks.cobblestone.getDefaultState());
/*  393 */     world.setBlockState(new BlockPos(i + 4, j + 12, k + 11), Blocks.cobblestone.getDefaultState());
/*  394 */     world.setBlockState(new BlockPos(i + 4, j + 12, k + 12), Blocks.cobblestone.getDefaultState());
/*  395 */     world.setBlockState(new BlockPos(i + 4, j + 12, k + 13), Blocks.cobblestone.getDefaultState());
/*  396 */     world.setBlockState(new BlockPos(i + 4, j + 12, k + 14), Blocks.dirt.getDefaultState());
/*  397 */     world.setBlockState(new BlockPos(i + 4, j + 12, k + 15), Blocks.grass.getDefaultState());
/*  398 */     world.setBlockState(new BlockPos(i + 4, j + 13, k + 5), Blocks.grass.getDefaultState());
/*  399 */     world.setBlockState(new BlockPos(i + 4, j + 13, k + 6), Blocks.grass.getDefaultState());
/*  400 */     world.setBlockState(new BlockPos(i + 4, j + 13, k + 7), Blocks.grass.getDefaultState());
/*  401 */     world.setBlockState(new BlockPos(i + 4, j + 13, k + 8), Blocks.grass.getDefaultState());
/*  402 */     world.setBlockState(new BlockPos(i + 4, j + 13, k + 9), Blocks.grass.getDefaultState());
/*  403 */     world.setBlockState(new BlockPos(i + 4, j + 13, k + 10), Blocks.grass.getDefaultState());
/*  404 */     world.setBlockState(new BlockPos(i + 4, j + 13, k + 11), Blocks.grass.getDefaultState());
/*  405 */     world.setBlockState(new BlockPos(i + 4, j + 13, k + 12), Blocks.grass.getDefaultState());
/*  406 */     world.setBlockState(new BlockPos(i + 4, j + 13, k + 13), Blocks.grass.getDefaultState());
/*  407 */     world.setBlockState(new BlockPos(i + 4, j + 13, k + 14), Blocks.grass.getDefaultState());
/*  408 */     world.setBlockState(new BlockPos(i + 5, j + 4, k + 3), Blocks.cobblestone.getDefaultState());
/*  409 */     world.setBlockState(new BlockPos(i + 5, j + 4, k + 4), Blocks.cobblestone.getDefaultState());
/*  410 */     world.setBlockState(new BlockPos(i + 5, j + 4, k + 5), Blocks.cobblestone.getDefaultState());
/*  411 */     world.setBlockState(new BlockPos(i + 5, j + 4, k + 6), Blocks.cobblestone.getDefaultState());
/*  412 */     world.setBlockState(new BlockPos(i + 5, j + 4, k + 7), Blocks.cobblestone.getDefaultState());
/*  413 */     world.setBlockState(new BlockPos(i + 5, j + 4, k + 8), Blocks.cobblestone.getDefaultState());
/*  414 */     world.setBlockState(new BlockPos(i + 5, j + 4, k + 9), Blocks.cobblestone.getDefaultState());
/*  415 */     world.setBlockState(new BlockPos(i + 5, j + 4, k + 10), Blocks.mossy_cobblestone.getDefaultState());
/*  416 */     world.setBlockState(new BlockPos(i + 5, j + 4, k + 11), Blocks.cobblestone.getDefaultState());
/*  417 */     world.setBlockState(new BlockPos(i + 5, j + 4, k + 12), Blocks.cobblestone.getDefaultState());
/*  418 */     world.setBlockState(new BlockPos(i + 5, j + 4, k + 13), Blocks.mossy_cobblestone.getDefaultState());
/*  419 */     world.setBlockState(new BlockPos(i + 5, j + 4, k + 14), Blocks.cobblestone.getDefaultState());
/*  420 */     world.setBlockState(new BlockPos(i + 5, j + 4, k + 15), Blocks.cobblestone.getDefaultState());
/*  421 */     world.setBlockState(new BlockPos(i + 5, j + 5, k + 3), Blocks.cobblestone.getDefaultState());
/*  422 */     world.setBlockState(new BlockPos(i + 5, j + 5, k + 15), Blocks.cobblestone.getDefaultState());
/*  423 */     world.setBlockState(new BlockPos(i + 5, j + 6, k + 3), Blocks.mossy_cobblestone.getDefaultState());
/*  424 */     world.setBlockState(new BlockPos(i + 5, j + 6, k + 15), Blocks.cobblestone.getDefaultState());
/*  425 */     world.setBlockState(new BlockPos(i + 5, j + 7, k + 3), Blocks.cobblestone.getDefaultState());
/*  426 */     world.setBlockState(new BlockPos(i + 5, j + 7, k + 15), Blocks.cobblestone.getDefaultState());
/*  427 */     world.setBlockState(new BlockPos(i + 5, j + 8, k + 0), Blocks.dirt.getDefaultState());
/*  428 */     world.setBlockState(new BlockPos(i + 5, j + 8, k + 1), Blocks.dirt.getDefaultState());
/*  429 */     world.setBlockState(new BlockPos(i + 5, j + 8, k + 2), Blocks.dirt.getDefaultState());
/*  430 */     world.setBlockState(new BlockPos(i + 5, j + 8, k + 3), Blocks.cobblestone.getDefaultState());
/*  431 */     world.setBlockState(new BlockPos(i + 5, j + 8, k + 4), Blocks.mossy_cobblestone.getDefaultState());
/*  432 */     world.setBlockState(new BlockPos(i + 5, j + 8, k + 5), Blocks.cobblestone.getDefaultState());
/*  433 */     world.setBlockState(new BlockPos(i + 5, j + 8, k + 6), Blocks.cobblestone.getDefaultState());
/*  434 */     world.setBlockState(new BlockPos(i + 5, j + 8, k + 7), Blocks.cobblestone.getDefaultState());
/*  435 */     world.setBlockState(new BlockPos(i + 5, j + 8, k + 8), Blocks.cobblestone.getDefaultState());
/*  436 */     world.setBlockState(new BlockPos(i + 5, j + 8, k + 9), Blocks.cobblestone.getDefaultState());
/*  437 */     world.setBlockState(new BlockPos(i + 5, j + 8, k + 10), Blocks.cobblestone.getDefaultState());
/*  438 */     world.setBlockState(new BlockPos(i + 5, j + 8, k + 11), Blocks.cobblestone.getDefaultState());
/*  439 */     world.setBlockState(new BlockPos(i + 5, j + 8, k + 12), Blocks.cobblestone.getDefaultState());
/*  440 */     world.setBlockState(new BlockPos(i + 5, j + 8, k + 13), Blocks.mossy_cobblestone.getDefaultState());
/*  441 */     world.setBlockState(new BlockPos(i + 5, j + 8, k + 14), Blocks.cobblestone.getDefaultState());
/*  442 */     world.setBlockState(new BlockPos(i + 5, j + 8, k + 15), Blocks.cobblestone.getDefaultState());
/*  443 */     world.setBlockState(new BlockPos(i + 5, j + 8, k + 16), Blocks.dirt.getDefaultState());
/*  444 */     world.setBlockState(new BlockPos(i + 5, j + 8, k + 17), Blocks.dirt.getDefaultState());
/*  445 */     world.setBlockState(new BlockPos(i + 5, j + 8, k + 18), Blocks.dirt.getDefaultState());
/*  446 */     world.setBlockState(new BlockPos(i + 5, j + 9, k + 0), Blocks.grass.getDefaultState());
/*  447 */     world.setBlockState(new BlockPos(i + 5, j + 9, k + 1), Blocks.dirt.getDefaultState());
/*  448 */     world.setBlockState(new BlockPos(i + 5, j + 9, k + 2), Blocks.dirt.getDefaultState());
/*  449 */     world.setBlockState(new BlockPos(i + 5, j + 9, k + 3), Blocks.cobblestone.getDefaultState());
/*  450 */     world.setBlockState(new BlockPos(i + 5, j + 9, k + 15), Blocks.cobblestone.getDefaultState());
/*  451 */     world.setBlockState(new BlockPos(i + 5, j + 9, k + 16), Blocks.dirt.getDefaultState());
/*  452 */     world.setBlockState(new BlockPos(i + 5, j + 9, k + 17), Blocks.dirt.getDefaultState());
/*  453 */     world.setBlockState(new BlockPos(i + 5, j + 9, k + 18), Blocks.grass.getDefaultState());
/*  454 */     world.setBlockState(new BlockPos(i + 5, j + 10, k + 1), Blocks.grass.getDefaultState());
/*  455 */     world.setBlockState(new BlockPos(i + 5, j + 10, k + 2), Blocks.dirt.getDefaultState());
/*  456 */     world.setBlockState(new BlockPos(i + 5, j + 10, k + 3), Blocks.cobblestone.getDefaultState());
/*  457 */     world.setBlockState(new BlockPos(i + 5, j + 10, k + 15), Blocks.cobblestone.getDefaultState());
/*  458 */     world.setBlockState(new BlockPos(i + 5, j + 10, k + 16), Blocks.dirt.getDefaultState());
/*  459 */     world.setBlockState(new BlockPos(i + 5, j + 10, k + 17), Blocks.grass.getDefaultState());
/*  460 */     world.setBlockState(new BlockPos(i + 5, j + 11, k + 2), Blocks.dirt.getDefaultState());
/*  461 */     world.setBlockState(new BlockPos(i + 5, j + 11, k + 3), Blocks.cobblestone.getDefaultState());
/*  462 */     world.setBlockState(new BlockPos(i + 5, j + 11, k + 6), Blocks.stone_stairs.getStateFromMeta(4));
/*  463 */     world.setBlockState(new BlockPos(i + 5, j + 11, k + 12), Blocks.stone_stairs.getStateFromMeta(4));
/*  464 */     world.setBlockState(new BlockPos(i + 5, j + 11, k + 15), Blocks.cobblestone.getDefaultState());
/*  465 */     world.setBlockState(new BlockPos(i + 5, j + 11, k + 16), Blocks.grass.getDefaultState());
/*  466 */     world.setBlockState(new BlockPos(i + 5, j + 12, k + 2), Blocks.grass.getDefaultState());
/*  467 */     world.setBlockState(new BlockPos(i + 5, j + 12, k + 3), Blocks.grass.getDefaultState());
/*  468 */     world.setBlockState(new BlockPos(i + 5, j + 12, k + 4), Blocks.cobblestone.getDefaultState());
/*  469 */     world.setBlockState(new BlockPos(i + 5, j + 12, k + 5), Blocks.cobblestone.getDefaultState());
/*  470 */     world.setBlockState(new BlockPos(i + 5, j + 12, k + 6), Blocks.cobblestone.getDefaultState());
/*  471 */     world.setBlockState(new BlockPos(i + 5, j + 12, k + 7), Blocks.cobblestone.getDefaultState());
/*  472 */     world.setBlockState(new BlockPos(i + 5, j + 12, k + 8), Blocks.cobblestone.getDefaultState());
/*  473 */     world.setBlockState(new BlockPos(i + 5, j + 12, k + 9), Blocks.cobblestone.getDefaultState());
/*  474 */     world.setBlockState(new BlockPos(i + 5, j + 12, k + 10), Blocks.cobblestone.getDefaultState());
/*  475 */     world.setBlockState(new BlockPos(i + 5, j + 12, k + 11), Blocks.cobblestone.getDefaultState());
/*  476 */     world.setBlockState(new BlockPos(i + 5, j + 12, k + 12), Blocks.mossy_cobblestone.getDefaultState());
/*  477 */     world.setBlockState(new BlockPos(i + 5, j + 12, k + 13), Blocks.cobblestone.getDefaultState());
/*  478 */     world.setBlockState(new BlockPos(i + 5, j + 12, k + 14), Blocks.cobblestone.getDefaultState());
/*  479 */     world.setBlockState(new BlockPos(i + 5, j + 12, k + 15), Blocks.dirt.getDefaultState());
/*  480 */     world.setBlockState(new BlockPos(i + 5, j + 13, k + 4), Blocks.grass.getDefaultState());
/*  481 */     world.setBlockState(new BlockPos(i + 5, j + 13, k + 5), Blocks.grass.getDefaultState());
/*  482 */     world.setBlockState(new BlockPos(i + 5, j + 13, k + 6), Blocks.grass.getDefaultState());
/*  483 */     world.setBlockState(new BlockPos(i + 5, j + 13, k + 7), Blocks.grass.getDefaultState());
/*  484 */     world.setBlockState(new BlockPos(i + 5, j + 13, k + 8), Blocks.grass.getDefaultState());
/*  485 */     world.setBlockState(new BlockPos(i + 5, j + 13, k + 9), Blocks.grass.getDefaultState());
/*  486 */     world.setBlockState(new BlockPos(i + 5, j + 13, k + 10), Blocks.grass.getDefaultState());
/*  487 */     world.setBlockState(new BlockPos(i + 5, j + 13, k + 11), Blocks.grass.getDefaultState());
/*  488 */     world.setBlockState(new BlockPos(i + 5, j + 13, k + 12), Blocks.grass.getDefaultState());
/*  489 */     world.setBlockState(new BlockPos(i + 5, j + 13, k + 13), Blocks.grass.getDefaultState());
/*  490 */     world.setBlockState(new BlockPos(i + 5, j + 13, k + 14), Blocks.grass.getDefaultState());
/*  491 */     world.setBlockState(new BlockPos(i + 5, j + 13, k + 15), Blocks.grass.getDefaultState());
/*  492 */     world.setBlockState(new BlockPos(i + 6, j + 0, k + 6), Blocks.cobblestone.getDefaultState());
/*  493 */     world.setBlockState(new BlockPos(i + 6, j + 0, k + 7), Blocks.cobblestone.getDefaultState());
/*  494 */     world.setBlockState(new BlockPos(i + 6, j + 0, k + 8), Blocks.cobblestone.getDefaultState());
/*  495 */     world.setBlockState(new BlockPos(i + 6, j + 0, k + 9), Blocks.cobblestone.getDefaultState());
/*  496 */     world.setBlockState(new BlockPos(i + 6, j + 0, k + 10), Blocks.cobblestone.getDefaultState());
/*  497 */     world.setBlockState(new BlockPos(i + 6, j + 0, k + 11), Blocks.cobblestone.getDefaultState());
/*  498 */     world.setBlockState(new BlockPos(i + 6, j + 0, k + 12), Blocks.cobblestone.getDefaultState());
/*  499 */     world.setBlockState(new BlockPos(i + 6, j + 1, k + 6), Blocks.mossy_cobblestone.getDefaultState());
/*  500 */     world.setBlockState(new BlockPos(i + 6, j + 1, k + 7), Blocks.cobblestone.getDefaultState());
/*  501 */     world.setBlockState(new BlockPos(i + 6, j + 1, k + 8), Blocks.cobblestone.getDefaultState());
/*  502 */     world.setBlockState(new BlockPos(i + 6, j + 1, k + 9), Blocks.mossy_cobblestone.getDefaultState());
/*  503 */     world.setBlockState(new BlockPos(i + 6, j + 1, k + 10), Blocks.mossy_cobblestone.getDefaultState());
/*  504 */     world.setBlockState(new BlockPos(i + 6, j + 1, k + 11), Blocks.cobblestone.getDefaultState());
/*  505 */     world.setBlockState(new BlockPos(i + 6, j + 1, k + 12), Blocks.cobblestone.getDefaultState());
/*  506 */     world.setBlockState(new BlockPos(i + 6, j + 2, k + 6), Blocks.cobblestone.getDefaultState());
/*  507 */     world.setBlockState(new BlockPos(i + 6, j + 2, k + 7), Blocks.cobblestone.getDefaultState());
/*  508 */     world.setBlockState(new BlockPos(i + 6, j + 2, k + 8), Blocks.cobblestone.getDefaultState());
/*  509 */     world.setBlockState(new BlockPos(i + 6, j + 2, k + 9), Blocks.cobblestone.getDefaultState());
/*  510 */     world.setBlockState(new BlockPos(i + 6, j + 2, k + 10), Blocks.cobblestone.getDefaultState());
/*  511 */     world.setBlockState(new BlockPos(i + 6, j + 2, k + 11), Blocks.cobblestone.getDefaultState());
/*  512 */     world.setBlockState(new BlockPos(i + 6, j + 2, k + 12), Blocks.cobblestone.getDefaultState());
/*  513 */     world.setBlockState(new BlockPos(i + 6, j + 3, k + 6), Blocks.cobblestone.getDefaultState());
/*  514 */     world.setBlockState(new BlockPos(i + 6, j + 3, k + 7), Blocks.cobblestone.getDefaultState());
/*  515 */     world.setBlockState(new BlockPos(i + 6, j + 3, k + 8), Blocks.mossy_cobblestone.getDefaultState());
/*  516 */     world.setBlockState(new BlockPos(i + 6, j + 3, k + 9), Blocks.cobblestone.getDefaultState());
/*  517 */     world.setBlockState(new BlockPos(i + 6, j + 3, k + 10), Blocks.cobblestone.getDefaultState());
/*  518 */     world.setBlockState(new BlockPos(i + 6, j + 3, k + 11), Blocks.cobblestone.getDefaultState());
/*  519 */     world.setBlockState(new BlockPos(i + 6, j + 3, k + 12), Blocks.cobblestone.getDefaultState());
/*  520 */     world.setBlockState(new BlockPos(i + 6, j + 4, k + 3), Blocks.cobblestone.getDefaultState());
/*  521 */     world.setBlockState(new BlockPos(i + 6, j + 4, k + 4), Blocks.cobblestone.getDefaultState());
/*  522 */     world.setBlockState(new BlockPos(i + 6, j + 4, k + 5), Blocks.cobblestone.getDefaultState());
/*  523 */     world.setBlockState(new BlockPos(i + 6, j + 4, k + 6), Blocks.cobblestone.getDefaultState());
/*  524 */     world.setBlockState(new BlockPos(i + 6, j + 4, k + 7), Blocks.stone_stairs.getStateFromMeta(1));
/*  525 */     world.setBlockState(new BlockPos(i + 6, j + 4, k + 8), Blocks.stone_stairs.getStateFromMeta(1));
/*  526 */     world.setBlockState(new BlockPos(i + 6, j + 4, k + 9), Blocks.cobblestone.getDefaultState());
/*  527 */     world.setBlockState(new BlockPos(i + 6, j + 4, k + 10), Blocks.stone_stairs.getStateFromMeta(1));
/*  528 */     world.setBlockState(new BlockPos(i + 6, j + 4, k + 11), Blocks.stone_stairs.getStateFromMeta(1));
/*  529 */     world.setBlockState(new BlockPos(i + 6, j + 4, k + 12), Blocks.cobblestone.getDefaultState());
/*  530 */     world.setBlockState(new BlockPos(i + 6, j + 4, k + 13), Blocks.cobblestone.getDefaultState());
/*  531 */     world.setBlockState(new BlockPos(i + 6, j + 4, k + 14), Blocks.cobblestone.getDefaultState());
/*  532 */     world.setBlockState(new BlockPos(i + 6, j + 4, k + 15), Blocks.cobblestone.getDefaultState());
/*  533 */     world.setBlockState(new BlockPos(i + 6, j + 5, k + 3), Blocks.cobblestone.getDefaultState());
/*  534 */     world.setBlockState(new BlockPos(i + 6, j + 5, k + 6), Blocks.mossy_cobblestone.getDefaultState());
/*  535 */     world.setBlockState(new BlockPos(i + 6, j + 5, k + 12), Blocks.cobblestone.getDefaultState());
/*  536 */     world.setBlockState(new BlockPos(i + 6, j + 5, k + 15), Blocks.mossy_cobblestone.getDefaultState());
/*  537 */     world.setBlockState(new BlockPos(i + 6, j + 6, k + 3), Blocks.cobblestone.getDefaultState());
/*  538 */     world.setBlockState(new BlockPos(i + 6, j + 6, k + 6), Blocks.mossy_cobblestone.getDefaultState());
/*  539 */     world.setBlockState(new BlockPos(i + 6, j + 6, k + 12), Blocks.cobblestone.getDefaultState());
/*  540 */     world.setBlockState(new BlockPos(i + 6, j + 6, k + 15), Blocks.cobblestone.getDefaultState());
/*  541 */     world.setBlockState(new BlockPos(i + 6, j + 7, k + 3), Blocks.cobblestone.getDefaultState());
/*  542 */     world.setBlockState(new BlockPos(i + 6, j + 7, k + 6), Blocks.cobblestone.getDefaultState());
/*  543 */     world.setBlockState(new BlockPos(i + 6, j + 7, k + 12), Blocks.cobblestone.getDefaultState());
/*  544 */     world.setBlockState(new BlockPos(i + 6, j + 7, k + 15), Blocks.cobblestone.getDefaultState());
/*  545 */     world.setBlockState(new BlockPos(i + 6, j + 8, k + 0), Blocks.dirt.getDefaultState());
/*  546 */     world.setBlockState(new BlockPos(i + 6, j + 8, k + 1), Blocks.dirt.getDefaultState());
/*  547 */     world.setBlockState(new BlockPos(i + 6, j + 8, k + 2), Blocks.dirt.getDefaultState());
/*  548 */     world.setBlockState(new BlockPos(i + 6, j + 8, k + 3), Blocks.cobblestone.getDefaultState());
/*  549 */     world.setBlockState(new BlockPos(i + 6, j + 8, k + 4), Blocks.cobblestone.getDefaultState());
/*  550 */     world.setBlockState(new BlockPos(i + 6, j + 8, k + 5), Blocks.cobblestone.getDefaultState());
/*  551 */     world.setBlockState(new BlockPos(i + 6, j + 8, k + 6), Blocks.cobblestone.getDefaultState());
/*  552 */     world.setBlockState(new BlockPos(i + 6, j + 8, k + 7), Blocks.stone_stairs.getStateFromMeta(5));
/*  553 */     world.setBlockState(new BlockPos(i + 6, j + 8, k + 8), Blocks.stone_stairs.getStateFromMeta(5));
/*  554 */     world.setBlockState(new BlockPos(i + 6, j + 8, k + 9), Blocks.stone_stairs.getStateFromMeta(5));
/*  555 */     world.setBlockState(new BlockPos(i + 6, j + 8, k + 10), Blocks.stone_stairs.getStateFromMeta(5));
/*  556 */     world.setBlockState(new BlockPos(i + 6, j + 8, k + 11), Blocks.stone_stairs.getStateFromMeta(5));
/*  557 */     world.setBlockState(new BlockPos(i + 6, j + 8, k + 12), Blocks.mossy_cobblestone.getDefaultState());
/*  558 */     world.setBlockState(new BlockPos(i + 6, j + 8, k + 13), Blocks.cobblestone.getDefaultState());
/*  559 */     world.setBlockState(new BlockPos(i + 6, j + 8, k + 14), Blocks.cobblestone.getDefaultState());
/*  560 */     world.setBlockState(new BlockPos(i + 6, j + 8, k + 15), Blocks.cobblestone.getDefaultState());
/*  561 */     world.setBlockState(new BlockPos(i + 6, j + 8, k + 16), Blocks.dirt.getDefaultState());
/*  562 */     world.setBlockState(new BlockPos(i + 6, j + 8, k + 17), Blocks.dirt.getDefaultState());
/*  563 */     world.setBlockState(new BlockPos(i + 6, j + 8, k + 18), Blocks.dirt.getDefaultState());
/*  564 */     world.setBlockState(new BlockPos(i + 6, j + 9, k + 0), Blocks.grass.getDefaultState());
/*  565 */     world.setBlockState(new BlockPos(i + 6, j + 9, k + 1), Blocks.dirt.getDefaultState());
/*  566 */     world.setBlockState(new BlockPos(i + 6, j + 9, k + 2), Blocks.dirt.getDefaultState());
/*  567 */     world.setBlockState(new BlockPos(i + 6, j + 9, k + 3), Blocks.cobblestone.getDefaultState());
/*  568 */     world.setBlockState(new BlockPos(i + 6, j + 9, k + 6), Blocks.mossy_cobblestone.getDefaultState());
/*  569 */     world.setBlockState(new BlockPos(i + 6, j + 9, k + 12), Blocks.cobblestone.getDefaultState());
/*  570 */     world.setBlockState(new BlockPos(i + 6, j + 9, k + 15), Blocks.cobblestone.getDefaultState());
/*  571 */     world.setBlockState(new BlockPos(i + 6, j + 9, k + 16), Blocks.dirt.getDefaultState());
/*  572 */     world.setBlockState(new BlockPos(i + 6, j + 9, k + 17), Blocks.dirt.getDefaultState());
/*  573 */     world.setBlockState(new BlockPos(i + 6, j + 9, k + 18), Blocks.grass.getDefaultState());
/*  574 */     world.setBlockState(new BlockPos(i + 6, j + 10, k + 1), Blocks.grass.getDefaultState());
/*  575 */     world.setBlockState(new BlockPos(i + 6, j + 10, k + 2), Blocks.dirt.getDefaultState());
/*  576 */     world.setBlockState(new BlockPos(i + 6, j + 10, k + 3), Blocks.cobblestone.getDefaultState());
/*  577 */     world.setBlockState(new BlockPos(i + 6, j + 10, k + 6), Blocks.cobblestone.getDefaultState());
/*  578 */     world.setBlockState(new BlockPos(i + 6, j + 10, k + 12), Blocks.mossy_cobblestone.getDefaultState());
/*  579 */     world.setBlockState(new BlockPos(i + 6, j + 10, k + 15), Blocks.cobblestone.getDefaultState());
/*  580 */     world.setBlockState(new BlockPos(i + 6, j + 10, k + 16), Blocks.dirt.getDefaultState());
/*  581 */     world.setBlockState(new BlockPos(i + 6, j + 10, k + 17), Blocks.grass.getDefaultState());
/*  582 */     world.setBlockState(new BlockPos(i + 6, j + 11, k + 2), Blocks.grass.getDefaultState());
/*  583 */     world.setBlockState(new BlockPos(i + 6, j + 11, k + 3), Blocks.cobblestone.getDefaultState());
/*  584 */     world.setBlockState(new BlockPos(i + 6, j + 11, k + 5), Blocks.stone_stairs.getStateFromMeta(6));
/*  585 */     world.setBlockState(new BlockPos(i + 6, j + 11, k + 6), Blocks.cobblestone.getDefaultState());
/*  586 */     world.setBlockState(new BlockPos(i + 6, j + 11, k + 7), Blocks.stone_stairs.getStateFromMeta(7));
/*  587 */     world.setBlockState(new BlockPos(i + 6, j + 11, k + 11), Blocks.stone_stairs.getStateFromMeta(6));
/*  588 */     world.setBlockState(new BlockPos(i + 6, j + 11, k + 12), Blocks.cobblestone.getDefaultState());
/*  589 */     world.setBlockState(new BlockPos(i + 6, j + 11, k + 13), Blocks.stone_stairs.getStateFromMeta(7));
/*  590 */     world.setBlockState(new BlockPos(i + 6, j + 11, k + 15), Blocks.mossy_cobblestone.getDefaultState());
/*  591 */     world.setBlockState(new BlockPos(i + 6, j + 11, k + 16), Blocks.grass.getDefaultState());
/*  592 */     world.setBlockState(new BlockPos(i + 6, j + 12, k + 3), Blocks.grass.getDefaultState());
/*  593 */     world.setBlockState(new BlockPos(i + 6, j + 12, k + 4), Blocks.cobblestone.getDefaultState());
/*  594 */     world.setBlockState(new BlockPos(i + 6, j + 12, k + 5), Blocks.cobblestone.getDefaultState());
/*  595 */     world.setBlockState(new BlockPos(i + 6, j + 12, k + 6), Blocks.mossy_cobblestone.getDefaultState());
/*  596 */     world.setBlockState(new BlockPos(i + 6, j + 12, k + 7), Blocks.cobblestone.getDefaultState());
/*  597 */     world.setBlockState(new BlockPos(i + 6, j + 12, k + 8), Blocks.cobblestone.getDefaultState());
/*  598 */     world.setBlockState(new BlockPos(i + 6, j + 12, k + 9), Blocks.mossy_cobblestone.getDefaultState());
/*  599 */     world.setBlockState(new BlockPos(i + 6, j + 12, k + 10), Blocks.cobblestone.getDefaultState());
/*  600 */     world.setBlockState(new BlockPos(i + 6, j + 12, k + 11), Blocks.cobblestone.getDefaultState());
/*  601 */     world.setBlockState(new BlockPos(i + 6, j + 12, k + 12), Blocks.cobblestone.getDefaultState());
/*  602 */     world.setBlockState(new BlockPos(i + 6, j + 12, k + 13), Blocks.cobblestone.getDefaultState());
/*  603 */     world.setBlockState(new BlockPos(i + 6, j + 12, k + 14), Blocks.cobblestone.getDefaultState());
/*  604 */     world.setBlockState(new BlockPos(i + 6, j + 12, k + 15), Blocks.grass.getDefaultState());
/*  605 */     world.setBlockState(new BlockPos(i + 6, j + 13, k + 4), Blocks.grass.getDefaultState());
/*  606 */     world.setBlockState(new BlockPos(i + 6, j + 13, k + 5), Blocks.grass.getDefaultState());
/*  607 */     world.setBlockState(new BlockPos(i + 6, j + 13, k + 6), Blocks.grass.getDefaultState());
/*  608 */     world.setBlockState(new BlockPos(i + 6, j + 13, k + 7), Blocks.grass.getDefaultState());
/*  609 */     world.setBlockState(new BlockPos(i + 6, j + 13, k + 8), Blocks.grass.getDefaultState());
/*  610 */     world.setBlockState(new BlockPos(i + 6, j + 13, k + 9), Blocks.grass.getDefaultState());
/*  611 */     world.setBlockState(new BlockPos(i + 6, j + 13, k + 10), Blocks.grass.getDefaultState());
/*  612 */     world.setBlockState(new BlockPos(i + 6, j + 13, k + 11), Blocks.grass.getDefaultState());
/*  613 */     world.setBlockState(new BlockPos(i + 6, j + 13, k + 12), Blocks.grass.getDefaultState());
/*  614 */     world.setBlockState(new BlockPos(i + 6, j + 13, k + 13), Blocks.grass.getDefaultState());
/*  615 */     world.setBlockState(new BlockPos(i + 6, j + 13, k + 14), Blocks.grass.getDefaultState());
/*  616 */     world.setBlockState(new BlockPos(i + 7, j + 0, k + 6), Blocks.cobblestone.getDefaultState());
/*  617 */     world.setBlockState(new BlockPos(i + 7, j + 0, k + 7), Blocks.mossy_cobblestone.getDefaultState());
/*  618 */     world.setBlockState(new BlockPos(i + 7, j + 0, k + 8), Blocks.cobblestone.getDefaultState());
/*  619 */     world.setBlockState(new BlockPos(i + 7, j + 0, k + 9), Blocks.cobblestone.getDefaultState());
/*  620 */     world.setBlockState(new BlockPos(i + 7, j + 0, k + 10), Blocks.mossy_cobblestone.getDefaultState());
/*  621 */     world.setBlockState(new BlockPos(i + 7, j + 0, k + 11), Blocks.mossy_cobblestone.getDefaultState());
/*  622 */     world.setBlockState(new BlockPos(i + 7, j + 0, k + 12), Blocks.cobblestone.getDefaultState());
/*  623 */     world.setBlockState(new BlockPos(i + 7, j + 1, k + 6), Blocks.mossy_cobblestone.getDefaultState());
/*  624 */     world.setBlockState(new BlockPos(i + 7, j + 1, k + 12), Blocks.cobblestone.getDefaultState());
/*  625 */     world.setBlockState(new BlockPos(i + 7, j + 2, k + 6), Blocks.cobblestone.getDefaultState());
/*  626 */     world.setBlockState(new BlockPos(i + 7, j + 2, k + 12), Blocks.cobblestone.getDefaultState());
/*  627 */     world.setBlockState(new BlockPos(i + 7, j + 3, k + 6), Blocks.cobblestone.getDefaultState());
/*  628 */     world.setBlockState(new BlockPos(i + 7, j + 3, k + 12), Blocks.cobblestone.getDefaultState());
/*  629 */     world.setBlockState(new BlockPos(i + 7, j + 4, k + 3), Blocks.cobblestone.getDefaultState());
/*  630 */     world.setBlockState(new BlockPos(i + 7, j + 4, k + 4), Blocks.cobblestone.getDefaultState());
/*  631 */     world.setBlockState(new BlockPos(i + 7, j + 4, k + 5), Blocks.cobblestone.getDefaultState());
/*  632 */     world.setBlockState(new BlockPos(i + 7, j + 4, k + 6), Blocks.stone_stairs.getDefaultState());
/*  633 */     world.setBlockState(new BlockPos(i + 7, j + 4, k + 12), Blocks.stone_stairs.getStateFromMeta(2));
/*  634 */     world.setBlockState(new BlockPos(i + 7, j + 4, k + 13), Blocks.cobblestone.getDefaultState());
/*  635 */     world.setBlockState(new BlockPos(i + 7, j + 4, k + 14), Blocks.cobblestone.getDefaultState());
/*  636 */     world.setBlockState(new BlockPos(i + 7, j + 4, k + 15), Blocks.cobblestone.getDefaultState());
/*  637 */     world.setBlockState(new BlockPos(i + 7, j + 5, k + 3), Blocks.cobblestone.getDefaultState());
/*  638 */     world.setBlockState(new BlockPos(i + 7, j + 5, k + 15), Blocks.cobblestone.getDefaultState());
/*  639 */     world.setBlockState(new BlockPos(i + 7, j + 6, k + 3), Blocks.cobblestone.getDefaultState());
/*  640 */     world.setBlockState(new BlockPos(i + 7, j + 6, k + 15), Blocks.mossy_cobblestone.getDefaultState());
/*  641 */     world.setBlockState(new BlockPos(i + 7, j + 7, k + 3), Blocks.cobblestone.getDefaultState());
/*  642 */     world.setBlockState(new BlockPos(i + 7, j + 7, k + 15), Blocks.cobblestone.getDefaultState());
/*  643 */     world.setBlockState(new BlockPos(i + 7, j + 8, k + 0), Blocks.dirt.getDefaultState());
/*  644 */     world.setBlockState(new BlockPos(i + 7, j + 8, k + 1), Blocks.dirt.getDefaultState());
/*  645 */     world.setBlockState(new BlockPos(i + 7, j + 8, k + 2), Blocks.dirt.getDefaultState());
/*  646 */     world.setBlockState(new BlockPos(i + 7, j + 8, k + 3), Blocks.cobblestone.getDefaultState());
/*  647 */     world.setBlockState(new BlockPos(i + 7, j + 8, k + 4), Blocks.cobblestone.getDefaultState());
/*  648 */     world.setBlockState(new BlockPos(i + 7, j + 8, k + 5), Blocks.cobblestone.getDefaultState());
/*  649 */     world.setBlockState(new BlockPos(i + 7, j + 8, k + 6), Blocks.stone_stairs.getStateFromMeta(7));
/*  650 */     world.setBlockState(new BlockPos(i + 7, j + 8, k + 12), Blocks.stone_stairs.getStateFromMeta(6));
/*  651 */     world.setBlockState(new BlockPos(i + 7, j + 8, k + 13), Blocks.cobblestone.getDefaultState());
/*  652 */     world.setBlockState(new BlockPos(i + 7, j + 8, k + 14), Blocks.mossy_cobblestone.getDefaultState());
/*  653 */     world.setBlockState(new BlockPos(i + 7, j + 8, k + 15), Blocks.cobblestone.getDefaultState());
/*  654 */     world.setBlockState(new BlockPos(i + 7, j + 8, k + 16), Blocks.dirt.getDefaultState());
/*  655 */     world.setBlockState(new BlockPos(i + 7, j + 8, k + 17), Blocks.dirt.getDefaultState());
/*  656 */     world.setBlockState(new BlockPos(i + 7, j + 8, k + 18), Blocks.dirt.getDefaultState());
/*  657 */     world.setBlockState(new BlockPos(i + 7, j + 9, k + 0), Blocks.grass.getDefaultState());
/*  658 */     world.setBlockState(new BlockPos(i + 7, j + 9, k + 1), Blocks.dirt.getDefaultState());
/*  659 */     world.setBlockState(new BlockPos(i + 7, j + 9, k + 2), Blocks.dirt.getDefaultState());
/*  660 */     world.setBlockState(new BlockPos(i + 7, j + 9, k + 3), Blocks.cobblestone.getDefaultState());
/*  661 */     world.setBlockState(new BlockPos(i + 7, j + 9, k + 15), Blocks.cobblestone.getDefaultState());
/*  662 */     world.setBlockState(new BlockPos(i + 7, j + 9, k + 16), Blocks.dirt.getDefaultState());
/*  663 */     world.setBlockState(new BlockPos(i + 7, j + 9, k + 17), Blocks.dirt.getDefaultState());
/*  664 */     world.setBlockState(new BlockPos(i + 7, j + 9, k + 18), Blocks.grass.getDefaultState());
/*  665 */     world.setBlockState(new BlockPos(i + 7, j + 10, k + 1), Blocks.dirt.getDefaultState());
/*  666 */     world.setBlockState(new BlockPos(i + 7, j + 10, k + 2), Blocks.dirt.getDefaultState());
/*  667 */     world.setBlockState(new BlockPos(i + 7, j + 10, k + 3), Blocks.cobblestone.getDefaultState());
/*  668 */     world.setBlockState(new BlockPos(i + 7, j + 10, k + 15), Blocks.cobblestone.getDefaultState());
/*  669 */     world.setBlockState(new BlockPos(i + 7, j + 10, k + 16), Blocks.dirt.getDefaultState());
/*  670 */     world.setBlockState(new BlockPos(i + 7, j + 10, k + 17), Blocks.dirt.getDefaultState());
/*  671 */     world.setBlockState(new BlockPos(i + 7, j + 11, k + 1), Blocks.grass.getDefaultState());
/*  672 */     world.setBlockState(new BlockPos(i + 7, j + 11, k + 2), Blocks.grass.getDefaultState());
/*  673 */     world.setBlockState(new BlockPos(i + 7, j + 11, k + 3), Blocks.mossy_cobblestone.getDefaultState());
/*  674 */     world.setBlockState(new BlockPos(i + 7, j + 11, k + 6), Blocks.stone_stairs.getStateFromMeta(5));
/*  675 */     world.setBlockState(new BlockPos(i + 7, j + 11, k + 12), Blocks.stone_stairs.getStateFromMeta(5));
/*  676 */     world.setBlockState(new BlockPos(i + 7, j + 11, k + 15), Blocks.cobblestone.getDefaultState());
/*  677 */     world.setBlockState(new BlockPos(i + 7, j + 11, k + 16), Blocks.grass.getDefaultState());
/*  678 */     world.setBlockState(new BlockPos(i + 7, j + 11, k + 17), Blocks.grass.getDefaultState());
/*  679 */     world.setBlockState(new BlockPos(i + 7, j + 12, k + 3), Blocks.grass.getDefaultState());
/*  680 */     world.setBlockState(new BlockPos(i + 7, j + 12, k + 4), Blocks.cobblestone.getDefaultState());
/*  681 */     world.setBlockState(new BlockPos(i + 7, j + 12, k + 5), Blocks.cobblestone.getDefaultState());
/*  682 */     world.setBlockState(new BlockPos(i + 7, j + 12, k + 6), Blocks.cobblestone.getDefaultState());
/*  683 */     world.setBlockState(new BlockPos(i + 7, j + 12, k + 7), Blocks.cobblestone.getDefaultState());
/*  684 */     world.setBlockState(new BlockPos(i + 7, j + 12, k + 8), Blocks.cobblestone.getDefaultState());
/*  685 */     world.setBlockState(new BlockPos(i + 7, j + 12, k + 9), Blocks.mossy_cobblestone.getDefaultState());
/*  686 */     world.setBlockState(new BlockPos(i + 7, j + 12, k + 10), Blocks.cobblestone.getDefaultState());
/*  687 */     world.setBlockState(new BlockPos(i + 7, j + 12, k + 11), Blocks.cobblestone.getDefaultState());
/*  688 */     world.setBlockState(new BlockPos(i + 7, j + 12, k + 12), Blocks.cobblestone.getDefaultState());
/*  689 */     world.setBlockState(new BlockPos(i + 7, j + 12, k + 13), Blocks.cobblestone.getDefaultState());
/*  690 */     world.setBlockState(new BlockPos(i + 7, j + 12, k + 14), Blocks.cobblestone.getDefaultState());
/*  691 */     world.setBlockState(new BlockPos(i + 7, j + 12, k + 15), Blocks.grass.getDefaultState());
/*  692 */     world.setBlockState(new BlockPos(i + 7, j + 13, k + 4), Blocks.grass.getDefaultState());
/*  693 */     world.setBlockState(new BlockPos(i + 7, j + 13, k + 5), Blocks.grass.getDefaultState());
/*  694 */     world.setBlockState(new BlockPos(i + 7, j + 13, k + 6), Blocks.grass.getDefaultState());
/*  695 */     world.setBlockState(new BlockPos(i + 7, j + 13, k + 7), Blocks.dirt.getDefaultState());
/*  696 */     world.setBlockState(new BlockPos(i + 7, j + 13, k + 8), Blocks.dirt.getDefaultState());
/*  697 */     world.setBlockState(new BlockPos(i + 7, j + 13, k + 9), Blocks.dirt.getDefaultState());
/*  698 */     world.setBlockState(new BlockPos(i + 7, j + 13, k + 10), Blocks.grass.getDefaultState());
/*  699 */     world.setBlockState(new BlockPos(i + 7, j + 13, k + 11), Blocks.grass.getDefaultState());
/*  700 */     world.setBlockState(new BlockPos(i + 7, j + 13, k + 12), Blocks.grass.getDefaultState());
/*  701 */     world.setBlockState(new BlockPos(i + 7, j + 13, k + 13), Blocks.grass.getDefaultState());
/*  702 */     world.setBlockState(new BlockPos(i + 7, j + 13, k + 14), Blocks.grass.getDefaultState());
/*  703 */     world.setBlockState(new BlockPos(i + 7, j + 14, k + 7), Blocks.grass.getDefaultState());
/*  704 */     world.setBlockState(new BlockPos(i + 7, j + 14, k + 8), Blocks.grass.getDefaultState());
/*  705 */     world.setBlockState(new BlockPos(i + 7, j + 14, k + 9), Blocks.grass.getDefaultState());
/*  706 */     world.setBlockState(new BlockPos(i + 8, j + 0, k + 6), Blocks.cobblestone.getDefaultState());
/*  707 */     world.setBlockState(new BlockPos(i + 8, j + 0, k + 7), Blocks.cobblestone.getDefaultState());
/*  708 */     world.setBlockState(new BlockPos(i + 8, j + 0, k + 8), Blocks.cobblestone.getDefaultState());
/*  709 */     world.setBlockState(new BlockPos(i + 8, j + 0, k + 9), Blocks.cobblestone.getDefaultState());
/*  710 */     world.setBlockState(new BlockPos(i + 8, j + 0, k + 10), Blocks.cobblestone.getDefaultState());
/*  711 */     world.setBlockState(new BlockPos(i + 8, j + 0, k + 11), Blocks.cobblestone.getDefaultState());
/*  712 */     world.setBlockState(new BlockPos(i + 8, j + 0, k + 12), Blocks.cobblestone.getDefaultState());
/*  713 */     world.setBlockState(new BlockPos(i + 8, j + 1, k + 6), Blocks.cobblestone.getDefaultState());
/*  714 */     world.setBlockState(new BlockPos(i + 8, j + 1, k + 12), Blocks.mossy_cobblestone.getDefaultState());
/*  715 */     world.setBlockState(new BlockPos(i + 8, j + 2, k + 6), Blocks.cobblestone.getDefaultState());
/*  716 */     world.setBlockState(new BlockPos(i + 8, j + 2, k + 12), Blocks.cobblestone.getDefaultState());
/*  717 */     world.setBlockState(new BlockPos(i + 8, j + 3, k + 6), Blocks.cobblestone.getDefaultState());
/*  718 */     world.setBlockState(new BlockPos(i + 8, j + 3, k + 12), Blocks.cobblestone.getDefaultState());
/*  719 */     world.setBlockState(new BlockPos(i + 8, j + 4, k + 3), Blocks.cobblestone.getDefaultState());
/*  720 */     world.setBlockState(new BlockPos(i + 8, j + 4, k + 4), Blocks.cobblestone.getDefaultState());
/*  721 */     world.setBlockState(new BlockPos(i + 8, j + 4, k + 5), Blocks.mossy_cobblestone.getDefaultState());
/*  722 */     world.setBlockState(new BlockPos(i + 8, j + 4, k + 6), Blocks.stone_stairs.getDefaultState());
/*  723 */     world.setBlockState(new BlockPos(i + 8, j + 4, k + 12), Blocks.stone_stairs.getStateFromMeta(2));
/*  724 */     world.setBlockState(new BlockPos(i + 8, j + 4, k + 13), Blocks.cobblestone.getDefaultState());
/*  725 */     world.setBlockState(new BlockPos(i + 8, j + 4, k + 14), Blocks.cobblestone.getDefaultState());
/*  726 */     world.setBlockState(new BlockPos(i + 8, j + 4, k + 15), Blocks.cobblestone.getDefaultState());
/*  727 */     world.setBlockState(new BlockPos(i + 8, j + 5, k + 3), Blocks.cobblestone.getDefaultState());
/*  728 */     world.setBlockState(new BlockPos(i + 8, j + 5, k + 15), Blocks.cobblestone.getDefaultState());
/*  729 */     world.setBlockState(new BlockPos(i + 8, j + 6, k + 3), Blocks.mossy_cobblestone.getDefaultState());
/*  730 */     world.setBlockState(new BlockPos(i + 8, j + 6, k + 15), Blocks.cobblestone.getDefaultState());
/*  731 */     world.setBlockState(new BlockPos(i + 8, j + 7, k + 3), Blocks.cobblestone.getDefaultState());
/*  732 */     world.setBlockState(new BlockPos(i + 8, j + 7, k + 15), Blocks.cobblestone.getDefaultState());
/*  733 */     world.setBlockState(new BlockPos(i + 8, j + 8, k + 0), Blocks.dirt.getDefaultState());
/*  734 */     world.setBlockState(new BlockPos(i + 8, j + 8, k + 1), Blocks.dirt.getDefaultState());
/*  735 */     world.setBlockState(new BlockPos(i + 8, j + 8, k + 2), Blocks.dirt.getDefaultState());
/*  736 */     world.setBlockState(new BlockPos(i + 8, j + 8, k + 3), Blocks.cobblestone.getDefaultState());
/*  737 */     world.setBlockState(new BlockPos(i + 8, j + 8, k + 4), Blocks.cobblestone.getDefaultState());
/*  738 */     world.setBlockState(new BlockPos(i + 8, j + 8, k + 5), Blocks.mossy_cobblestone.getDefaultState());
/*  739 */     world.setBlockState(new BlockPos(i + 8, j + 8, k + 6), Blocks.stone_stairs.getStateFromMeta(7));
/*  740 */     world.setBlockState(new BlockPos(i + 8, j + 8, k + 12), Blocks.stone_stairs.getStateFromMeta(6));
/*  741 */     world.setBlockState(new BlockPos(i + 8, j + 8, k + 13), Blocks.cobblestone.getDefaultState());
/*  742 */     world.setBlockState(new BlockPos(i + 8, j + 8, k + 14), Blocks.cobblestone.getDefaultState());
/*  743 */     world.setBlockState(new BlockPos(i + 8, j + 8, k + 15), Blocks.cobblestone.getDefaultState());
/*  744 */     world.setBlockState(new BlockPos(i + 8, j + 8, k + 16), Blocks.dirt.getDefaultState());
/*  745 */     world.setBlockState(new BlockPos(i + 8, j + 8, k + 17), Blocks.dirt.getDefaultState());
/*  746 */     world.setBlockState(new BlockPos(i + 8, j + 8, k + 18), Blocks.dirt.getDefaultState());
/*  747 */     world.setBlockState(new BlockPos(i + 8, j + 9, k + 0), Blocks.grass.getDefaultState());
/*  748 */     world.setBlockState(new BlockPos(i + 8, j + 9, k + 1), Blocks.dirt.getDefaultState());
/*  749 */     world.setBlockState(new BlockPos(i + 8, j + 9, k + 2), Blocks.dirt.getDefaultState());
/*  750 */     world.setBlockState(new BlockPos(i + 8, j + 9, k + 3), Blocks.cobblestone.getDefaultState());
/*  751 */     world.setBlockState(new BlockPos(i + 8, j + 9, k + 15), Blocks.cobblestone.getDefaultState());
/*  752 */     world.setBlockState(new BlockPos(i + 8, j + 9, k + 16), Blocks.dirt.getDefaultState());
/*  753 */     world.setBlockState(new BlockPos(i + 8, j + 9, k + 17), Blocks.dirt.getDefaultState());
/*  754 */     world.setBlockState(new BlockPos(i + 8, j + 9, k + 18), Blocks.grass.getDefaultState());
/*  755 */     world.setBlockState(new BlockPos(i + 8, j + 10, k + 1), Blocks.grass.getDefaultState());
/*  756 */     world.setBlockState(new BlockPos(i + 8, j + 10, k + 2), Blocks.dirt.getDefaultState());
/*  757 */     world.setBlockState(new BlockPos(i + 8, j + 10, k + 3), Blocks.mossy_cobblestone.getDefaultState());
/*  758 */     world.setBlockState(new BlockPos(i + 8, j + 10, k + 15), Blocks.mossy_cobblestone.getDefaultState());
/*  759 */     world.setBlockState(new BlockPos(i + 8, j + 10, k + 16), Blocks.dirt.getDefaultState());
/*  760 */     world.setBlockState(new BlockPos(i + 8, j + 10, k + 17), Blocks.dirt.getDefaultState());
/*  761 */     world.setBlockState(new BlockPos(i + 8, j + 11, k + 2), Blocks.grass.getDefaultState());
/*  762 */     world.setBlockState(new BlockPos(i + 8, j + 11, k + 3), Blocks.cobblestone.getDefaultState());
/*  763 */     world.setBlockState(new BlockPos(i + 8, j + 11, k + 15), Blocks.cobblestone.getDefaultState());
/*  764 */     world.setBlockState(new BlockPos(i + 8, j + 11, k + 16), Blocks.grass.getDefaultState());
/*  765 */     world.setBlockState(new BlockPos(i + 8, j + 11, k + 17), Blocks.grass.getDefaultState());
/*  766 */     world.setBlockState(new BlockPos(i + 8, j + 12, k + 3), Blocks.grass.getDefaultState());
/*  767 */     world.setBlockState(new BlockPos(i + 8, j + 12, k + 4), Blocks.cobblestone.getDefaultState());
/*  768 */     world.setBlockState(new BlockPos(i + 8, j + 12, k + 5), Blocks.cobblestone.getDefaultState());
/*  769 */     world.setBlockState(new BlockPos(i + 8, j + 12, k + 6), Blocks.cobblestone.getDefaultState());
/*  770 */     world.setBlockState(new BlockPos(i + 8, j + 12, k + 7), Blocks.mossy_cobblestone.getDefaultState());
/*  771 */     world.setBlockState(new BlockPos(i + 8, j + 12, k + 8), Blocks.cobblestone.getDefaultState());
/*  772 */     world.setBlockState(new BlockPos(i + 8, j + 12, k + 9), Blocks.cobblestone.getDefaultState());
/*  773 */     world.setBlockState(new BlockPos(i + 8, j + 12, k + 10), Blocks.cobblestone.getDefaultState());
/*  774 */     world.setBlockState(new BlockPos(i + 8, j + 12, k + 11), Blocks.cobblestone.getDefaultState());
/*  775 */     world.setBlockState(new BlockPos(i + 8, j + 12, k + 12), Blocks.cobblestone.getDefaultState());
/*  776 */     world.setBlockState(new BlockPos(i + 8, j + 12, k + 13), Blocks.cobblestone.getDefaultState());
/*  777 */     world.setBlockState(new BlockPos(i + 8, j + 12, k + 14), Blocks.cobblestone.getDefaultState());
/*  778 */     world.setBlockState(new BlockPos(i + 8, j + 12, k + 15), Blocks.grass.getDefaultState());
/*  779 */     world.setBlockState(new BlockPos(i + 8, j + 13, k + 4), Blocks.grass.getDefaultState());
/*  780 */     world.setBlockState(new BlockPos(i + 8, j + 13, k + 5), Blocks.grass.getDefaultState());
/*  781 */     world.setBlockState(new BlockPos(i + 8, j + 13, k + 6), Blocks.dirt.getDefaultState());
/*  782 */     world.setBlockState(new BlockPos(i + 8, j + 13, k + 7), Blocks.dirt.getDefaultState());
/*  783 */     world.setBlockState(new BlockPos(i + 8, j + 13, k + 8), Blocks.dirt.getDefaultState());
/*  784 */     world.setBlockState(new BlockPos(i + 8, j + 13, k + 9), Blocks.dirt.getDefaultState());
/*  785 */     world.setBlockState(new BlockPos(i + 8, j + 13, k + 10), Blocks.dirt.getDefaultState());
/*  786 */     world.setBlockState(new BlockPos(i + 8, j + 13, k + 11), Blocks.grass.getDefaultState());
/*  787 */     world.setBlockState(new BlockPos(i + 8, j + 13, k + 12), Blocks.grass.getDefaultState());
/*  788 */     world.setBlockState(new BlockPos(i + 8, j + 13, k + 13), Blocks.grass.getDefaultState());
/*  789 */     world.setBlockState(new BlockPos(i + 8, j + 13, k + 14), Blocks.grass.getDefaultState());
/*  790 */     world.setBlockState(new BlockPos(i + 8, j + 14, k + 6), Blocks.grass.getDefaultState());
/*  791 */     world.setBlockState(new BlockPos(i + 8, j + 14, k + 7), Blocks.grass.getDefaultState());
/*  792 */     world.setBlockState(new BlockPos(i + 8, j + 14, k + 8), Blocks.grass.getDefaultState());
/*  793 */     world.setBlockState(new BlockPos(i + 8, j + 14, k + 9), Blocks.grass.getDefaultState());
/*  794 */     world.setBlockState(new BlockPos(i + 8, j + 14, k + 10), Blocks.grass.getDefaultState());
/*  795 */     world.setBlockState(new BlockPos(i + 9, j + 0, k + 6), Blocks.cobblestone.getDefaultState());
/*  796 */     world.setBlockState(new BlockPos(i + 9, j + 0, k + 7), Blocks.cobblestone.getDefaultState());
/*  797 */     world.setBlockState(new BlockPos(i + 9, j + 0, k + 8), Blocks.mossy_cobblestone.getDefaultState());
/*  798 */     world.setBlockState(new BlockPos(i + 9, j + 0, k + 9), Blocks.cobblestone.getDefaultState());
/*  799 */     world.setBlockState(new BlockPos(i + 9, j + 0, k + 10), Blocks.mossy_cobblestone.getDefaultState());
/*  800 */     world.setBlockState(new BlockPos(i + 9, j + 0, k + 11), Blocks.mossy_cobblestone.getDefaultState());
/*  801 */     world.setBlockState(new BlockPos(i + 9, j + 0, k + 12), Blocks.cobblestone.getDefaultState());
/*  802 */     world.setBlockState(new BlockPos(i + 9, j + 1, k + 6), Blocks.mossy_cobblestone.getDefaultState());
/*      */     
/*  804 */     world.setBlockState(new BlockPos(i + 9, j + 1, k + 12), Blocks.mossy_cobblestone.getDefaultState());
/*  805 */     world.setBlockState(new BlockPos(i + 9, j + 2, k + 6), Blocks.cobblestone.getDefaultState());
/*  806 */     world.setBlockState(new BlockPos(i + 9, j + 2, k + 12), Blocks.cobblestone.getDefaultState());
/*  807 */     world.setBlockState(new BlockPos(i + 9, j + 3, k + 6), Blocks.cobblestone.getDefaultState());
/*  808 */     world.setBlockState(new BlockPos(i + 9, j + 3, k + 12), Blocks.mossy_cobblestone.getDefaultState());
/*  809 */     world.setBlockState(new BlockPos(i + 9, j + 4, k + 3), Blocks.cobblestone.getDefaultState());
/*  810 */     world.setBlockState(new BlockPos(i + 9, j + 4, k + 4), Blocks.cobblestone.getDefaultState());
/*  811 */     world.setBlockState(new BlockPos(i + 9, j + 4, k + 5), Blocks.cobblestone.getDefaultState());
/*  812 */     world.setBlockState(new BlockPos(i + 9, j + 4, k + 6), Blocks.stone_stairs.getDefaultState());
/*  813 */     world.setBlockState(new BlockPos(i + 9, j + 4, k + 12), Blocks.stone_stairs.getStateFromMeta(2));
/*  814 */     world.setBlockState(new BlockPos(i + 9, j + 4, k + 13), Blocks.cobblestone.getDefaultState());
/*  815 */     world.setBlockState(new BlockPos(i + 9, j + 4, k + 14), Blocks.cobblestone.getDefaultState());
/*  816 */     world.setBlockState(new BlockPos(i + 9, j + 4, k + 15), Blocks.cobblestone.getDefaultState());
/*  817 */     world.setBlockState(new BlockPos(i + 9, j + 5, k + 3), Blocks.cobblestone.getDefaultState());
/*  818 */     world.setBlockState(new BlockPos(i + 9, j + 5, k + 15), Blocks.cobblestone.getDefaultState());
/*  819 */     world.setBlockState(new BlockPos(i + 9, j + 6, k + 3), Blocks.cobblestone.getDefaultState());
/*  820 */     world.setBlockState(new BlockPos(i + 9, j + 6, k + 15), Blocks.cobblestone.getDefaultState());
/*  821 */     world.setBlockState(new BlockPos(i + 9, j + 7, k + 3), Blocks.cobblestone.getDefaultState());
/*  822 */     world.setBlockState(new BlockPos(i + 9, j + 7, k + 15), Blocks.cobblestone.getDefaultState());
/*  823 */     world.setBlockState(new BlockPos(i + 9, j + 8, k + 0), Blocks.dirt.getDefaultState());
/*  824 */     world.setBlockState(new BlockPos(i + 9, j + 8, k + 1), Blocks.dirt.getDefaultState());
/*  825 */     world.setBlockState(new BlockPos(i + 9, j + 8, k + 2), Blocks.dirt.getDefaultState());
/*  826 */     world.setBlockState(new BlockPos(i + 9, j + 8, k + 3), Blocks.cobblestone.getDefaultState());
/*  827 */     world.setBlockState(new BlockPos(i + 9, j + 8, k + 4), Blocks.cobblestone.getDefaultState());
/*  828 */     world.setBlockState(new BlockPos(i + 9, j + 8, k + 5), Blocks.cobblestone.getDefaultState());
/*  829 */     world.setBlockState(new BlockPos(i + 9, j + 8, k + 6), Blocks.stone_stairs.getStateFromMeta(7));
/*  830 */     world.setBlockState(new BlockPos(i + 9, j + 8, k + 12), Blocks.stone_stairs.getStateFromMeta(6));
/*  831 */     world.setBlockState(new BlockPos(i + 9, j + 8, k + 13), Blocks.mossy_cobblestone.getDefaultState());
/*  832 */     world.setBlockState(new BlockPos(i + 9, j + 8, k + 14), Blocks.cobblestone.getDefaultState());
/*  833 */     world.setBlockState(new BlockPos(i + 9, j + 8, k + 15), Blocks.cobblestone.getDefaultState());
/*  834 */     world.setBlockState(new BlockPos(i + 9, j + 8, k + 16), Blocks.dirt.getDefaultState());
/*  835 */     world.setBlockState(new BlockPos(i + 9, j + 8, k + 17), Blocks.dirt.getDefaultState());
/*  836 */     world.setBlockState(new BlockPos(i + 9, j + 8, k + 18), Blocks.dirt.getDefaultState());
/*  837 */     world.setBlockState(new BlockPos(i + 9, j + 9, k + 0), Blocks.dirt.getDefaultState());
/*  838 */     world.setBlockState(new BlockPos(i + 9, j + 9, k + 1), Blocks.dirt.getDefaultState());
/*  839 */     world.setBlockState(new BlockPos(i + 9, j + 9, k + 2), Blocks.dirt.getDefaultState());
/*  840 */     world.setBlockState(new BlockPos(i + 9, j + 9, k + 3), Blocks.cobblestone.getDefaultState());
/*  841 */     world.setBlockState(new BlockPos(i + 9, j + 9, k + 15), Blocks.mossy_cobblestone.getDefaultState());
/*  842 */     world.setBlockState(new BlockPos(i + 9, j + 9, k + 16), Blocks.dirt.getDefaultState());
/*  843 */     world.setBlockState(new BlockPos(i + 9, j + 9, k + 17), Blocks.dirt.getDefaultState());
/*  844 */     world.setBlockState(new BlockPos(i + 9, j + 9, k + 18), Blocks.grass.getDefaultState());
/*  845 */     world.setBlockState(new BlockPos(i + 9, j + 10, k + 0), Blocks.grass.getDefaultState());
/*  846 */     world.setBlockState(new BlockPos(i + 9, j + 10, k + 1), Blocks.dirt.getDefaultState());
/*  847 */     world.setBlockState(new BlockPos(i + 9, j + 10, k + 2), Blocks.dirt.getDefaultState());
/*  848 */     world.setBlockState(new BlockPos(i + 9, j + 10, k + 3), Blocks.mossy_cobblestone.getDefaultState());
/*  849 */     world.setBlockState(new BlockPos(i + 9, j + 10, k + 15), Blocks.mossy_cobblestone.getDefaultState());
/*  850 */     world.setBlockState(new BlockPos(i + 9, j + 10, k + 16), Blocks.dirt.getDefaultState());
/*  851 */     world.setBlockState(new BlockPos(i + 9, j + 10, k + 17), Blocks.grass.getDefaultState());
/*  852 */     world.setBlockState(new BlockPos(i + 9, j + 11, k + 1), Blocks.grass.getDefaultState());
/*  853 */     world.setBlockState(new BlockPos(i + 9, j + 11, k + 2), Blocks.dirt.getDefaultState());
/*  854 */     world.setBlockState(new BlockPos(i + 9, j + 11, k + 3), Blocks.cobblestone.getDefaultState());
/*  855 */     world.setBlockState(new BlockPos(i + 9, j + 11, k + 15), Blocks.cobblestone.getDefaultState());
/*  856 */     world.setBlockState(new BlockPos(i + 9, j + 11, k + 16), Blocks.dirt.getDefaultState());
/*  857 */     world.setBlockState(new BlockPos(i + 9, j + 12, k + 2), Blocks.grass.getDefaultState());
/*  858 */     world.setBlockState(new BlockPos(i + 9, j + 12, k + 3), Blocks.grass.getDefaultState());
/*  859 */     world.setBlockState(new BlockPos(i + 9, j + 12, k + 4), Blocks.cobblestone.getDefaultState());
/*  860 */     world.setBlockState(new BlockPos(i + 9, j + 12, k + 5), Blocks.cobblestone.getDefaultState());
/*  861 */     world.setBlockState(new BlockPos(i + 9, j + 12, k + 6), Blocks.cobblestone.getDefaultState());
/*  862 */     world.setBlockState(new BlockPos(i + 9, j + 12, k + 7), Blocks.mossy_cobblestone.getDefaultState());
/*  863 */     world.setBlockState(new BlockPos(i + 9, j + 12, k + 8), Blocks.cobblestone.getDefaultState());
/*  864 */     world.setBlockState(new BlockPos(i + 9, j + 12, k + 9), Blocks.cobblestone.getDefaultState());
/*  865 */     world.setBlockState(new BlockPos(i + 9, j + 12, k + 10), Blocks.cobblestone.getDefaultState());
/*  866 */     world.setBlockState(new BlockPos(i + 9, j + 12, k + 11), Blocks.cobblestone.getDefaultState());
/*  867 */     world.setBlockState(new BlockPos(i + 9, j + 12, k + 12), Blocks.cobblestone.getDefaultState());
/*  868 */     world.setBlockState(new BlockPos(i + 9, j + 12, k + 13), Blocks.cobblestone.getDefaultState());
/*  869 */     world.setBlockState(new BlockPos(i + 9, j + 12, k + 14), Blocks.cobblestone.getDefaultState());
/*  870 */     world.setBlockState(new BlockPos(i + 9, j + 12, k + 15), Blocks.grass.getDefaultState());
/*  871 */     world.setBlockState(new BlockPos(i + 9, j + 12, k + 16), Blocks.grass.getDefaultState());
/*  872 */     world.setBlockState(new BlockPos(i + 9, j + 13, k + 4), Blocks.grass.getDefaultState());
/*  873 */     world.setBlockState(new BlockPos(i + 9, j + 13, k + 5), Blocks.grass.getDefaultState());
/*  874 */     world.setBlockState(new BlockPos(i + 9, j + 13, k + 6), Blocks.dirt.getDefaultState());
/*  875 */     world.setBlockState(new BlockPos(i + 9, j + 13, k + 7), Blocks.dirt.getDefaultState());
/*  876 */     world.setBlockState(new BlockPos(i + 9, j + 13, k + 8), Blocks.dirt.getDefaultState());
/*  877 */     world.setBlockState(new BlockPos(i + 9, j + 13, k + 9), Blocks.dirt.getDefaultState());
/*  878 */     world.setBlockState(new BlockPos(i + 9, j + 13, k + 10), Blocks.dirt.getDefaultState());
/*  879 */     world.setBlockState(new BlockPos(i + 9, j + 13, k + 11), Blocks.dirt.getDefaultState());
/*  880 */     world.setBlockState(new BlockPos(i + 9, j + 13, k + 12), Blocks.grass.getDefaultState());
/*  881 */     world.setBlockState(new BlockPos(i + 9, j + 13, k + 13), Blocks.grass.getDefaultState());
/*  882 */     world.setBlockState(new BlockPos(i + 9, j + 13, k + 14), Blocks.grass.getDefaultState());
/*  883 */     world.setBlockState(new BlockPos(i + 9, j + 14, k + 6), Blocks.grass.getDefaultState());
/*  884 */     world.setBlockState(new BlockPos(i + 9, j + 14, k + 7), Blocks.grass.getDefaultState());
/*  885 */     world.setBlockState(new BlockPos(i + 9, j + 14, k + 8), Blocks.grass.getDefaultState());
/*  886 */     world.setBlockState(new BlockPos(i + 9, j + 14, k + 9), Blocks.grass.getDefaultState());
/*  887 */     world.setBlockState(new BlockPos(i + 9, j + 14, k + 10), Blocks.grass.getDefaultState());
/*  888 */     world.setBlockState(new BlockPos(i + 9, j + 14, k + 11), Blocks.grass.getDefaultState());
/*  889 */     world.setBlockState(new BlockPos(i + 10, j + 0, k + 6), Blocks.cobblestone.getDefaultState());
/*  890 */     world.setBlockState(new BlockPos(i + 10, j + 0, k + 7), Blocks.mossy_cobblestone.getDefaultState());
/*  891 */     world.setBlockState(new BlockPos(i + 10, j + 0, k + 8), Blocks.mossy_cobblestone.getDefaultState());
/*  892 */     world.setBlockState(new BlockPos(i + 10, j + 0, k + 9), Blocks.cobblestone.getDefaultState());
/*  893 */     world.setBlockState(new BlockPos(i + 10, j + 0, k + 10), Blocks.cobblestone.getDefaultState());
/*  894 */     world.setBlockState(new BlockPos(i + 10, j + 0, k + 11), Blocks.mossy_cobblestone.getDefaultState());
/*  895 */     world.setBlockState(new BlockPos(i + 10, j + 0, k + 12), Blocks.cobblestone.getDefaultState());
/*  896 */     world.setBlockState(new BlockPos(i + 10, j + 1, k + 6), Blocks.cobblestone.getDefaultState());
/*      */     
/*  898 */     world.setBlockState(new BlockPos(i + 10, j + 1, k + 12), Blocks.cobblestone.getDefaultState());
/*  899 */     world.setBlockState(new BlockPos(i + 10, j + 2, k + 6), Blocks.cobblestone.getDefaultState());
/*  900 */     world.setBlockState(new BlockPos(i + 10, j + 2, k + 12), Blocks.cobblestone.getDefaultState());
/*  901 */     world.setBlockState(new BlockPos(i + 10, j + 3, k + 6), Blocks.cobblestone.getDefaultState());
/*  902 */     world.setBlockState(new BlockPos(i + 10, j + 3, k + 12), Blocks.cobblestone.getDefaultState());
/*  903 */     world.setBlockState(new BlockPos(i + 10, j + 4, k + 3), Blocks.cobblestone.getDefaultState());
/*  904 */     world.setBlockState(new BlockPos(i + 10, j + 4, k + 4), Blocks.mossy_cobblestone.getDefaultState());
/*  905 */     world.setBlockState(new BlockPos(i + 10, j + 4, k + 5), Blocks.cobblestone.getDefaultState());
/*  906 */     world.setBlockState(new BlockPos(i + 10, j + 4, k + 6), Blocks.stone_stairs.getDefaultState());
/*  907 */     world.setBlockState(new BlockPos(i + 10, j + 4, k + 12), Blocks.stone_stairs.getStateFromMeta(2));
/*  908 */     world.setBlockState(new BlockPos(i + 10, j + 4, k + 13), Blocks.cobblestone.getDefaultState());
/*  909 */     world.setBlockState(new BlockPos(i + 10, j + 4, k + 14), Blocks.cobblestone.getDefaultState());
/*  910 */     world.setBlockState(new BlockPos(i + 10, j + 4, k + 15), Blocks.cobblestone.getDefaultState());
/*  911 */     world.setBlockState(new BlockPos(i + 10, j + 5, k + 3), Blocks.cobblestone.getDefaultState());
/*  912 */     world.setBlockState(new BlockPos(i + 10, j + 5, k + 15), Blocks.cobblestone.getDefaultState());
/*  913 */     world.setBlockState(new BlockPos(i + 10, j + 6, k + 3), Blocks.cobblestone.getDefaultState());
/*  914 */     world.setBlockState(new BlockPos(i + 10, j + 6, k + 15), Blocks.mossy_cobblestone.getDefaultState());
/*  915 */     world.setBlockState(new BlockPos(i + 10, j + 7, k + 3), Blocks.cobblestone.getDefaultState());
/*  916 */     world.setBlockState(new BlockPos(i + 10, j + 7, k + 15), Blocks.cobblestone.getDefaultState());
/*  917 */     world.setBlockState(new BlockPos(i + 10, j + 8, k + 0), Blocks.dirt.getDefaultState());
/*  918 */     world.setBlockState(new BlockPos(i + 10, j + 8, k + 1), Blocks.dirt.getDefaultState());
/*  919 */     world.setBlockState(new BlockPos(i + 10, j + 8, k + 2), Blocks.dirt.getDefaultState());
/*  920 */     world.setBlockState(new BlockPos(i + 10, j + 8, k + 3), Blocks.cobblestone.getDefaultState());
/*  921 */     world.setBlockState(new BlockPos(i + 10, j + 8, k + 4), Blocks.mossy_cobblestone.getDefaultState());
/*  922 */     world.setBlockState(new BlockPos(i + 10, j + 8, k + 5), Blocks.cobblestone.getDefaultState());
/*  923 */     world.setBlockState(new BlockPos(i + 10, j + 8, k + 6), Blocks.stone_stairs.getStateFromMeta(7));
/*  924 */     world.setBlockState(new BlockPos(i + 10, j + 8, k + 12), Blocks.stone_stairs.getStateFromMeta(6));
/*  925 */     world.setBlockState(new BlockPos(i + 10, j + 8, k + 13), Blocks.cobblestone.getDefaultState());
/*  926 */     world.setBlockState(new BlockPos(i + 10, j + 8, k + 14), Blocks.cobblestone.getDefaultState());
/*  927 */     world.setBlockState(new BlockPos(i + 10, j + 8, k + 15), Blocks.cobblestone.getDefaultState());
/*  928 */     world.setBlockState(new BlockPos(i + 10, j + 8, k + 16), Blocks.dirt.getDefaultState());
/*  929 */     world.setBlockState(new BlockPos(i + 10, j + 8, k + 17), Blocks.dirt.getDefaultState());
/*  930 */     world.setBlockState(new BlockPos(i + 10, j + 8, k + 18), Blocks.dirt.getDefaultState());
/*  931 */     world.setBlockState(new BlockPos(i + 10, j + 9, k + 0), Blocks.dirt.getDefaultState());
/*  932 */     world.setBlockState(new BlockPos(i + 10, j + 9, k + 1), Blocks.dirt.getDefaultState());
/*  933 */     world.setBlockState(new BlockPos(i + 10, j + 9, k + 2), Blocks.dirt.getDefaultState());
/*  934 */     world.setBlockState(new BlockPos(i + 10, j + 9, k + 3), Blocks.cobblestone.getDefaultState());
/*  935 */     world.setBlockState(new BlockPos(i + 10, j + 9, k + 15), Blocks.cobblestone.getDefaultState());
/*  936 */     world.setBlockState(new BlockPos(i + 10, j + 9, k + 16), Blocks.dirt.getDefaultState());
/*  937 */     world.setBlockState(new BlockPos(i + 10, j + 9, k + 17), Blocks.dirt.getDefaultState());
/*  938 */     world.setBlockState(new BlockPos(i + 10, j + 9, k + 18), Blocks.grass.getDefaultState());
/*  939 */     world.setBlockState(new BlockPos(i + 10, j + 10, k + 0), Blocks.grass.getDefaultState());
/*  940 */     world.setBlockState(new BlockPos(i + 10, j + 10, k + 1), Blocks.dirt.getDefaultState());
/*  941 */     world.setBlockState(new BlockPos(i + 10, j + 10, k + 2), Blocks.dirt.getDefaultState());
/*  942 */     world.setBlockState(new BlockPos(i + 10, j + 10, k + 3), Blocks.cobblestone.getDefaultState());
/*  943 */     world.setBlockState(new BlockPos(i + 10, j + 10, k + 15), Blocks.cobblestone.getDefaultState());
/*  944 */     world.setBlockState(new BlockPos(i + 10, j + 10, k + 16), Blocks.dirt.getDefaultState());
/*  945 */     world.setBlockState(new BlockPos(i + 10, j + 10, k + 17), Blocks.grass.getDefaultState());
/*  946 */     world.setBlockState(new BlockPos(i + 10, j + 11, k + 1), Blocks.grass.getDefaultState());
/*  947 */     world.setBlockState(new BlockPos(i + 10, j + 11, k + 2), Blocks.grass.getDefaultState());
/*  948 */     world.setBlockState(new BlockPos(i + 10, j + 11, k + 3), Blocks.cobblestone.getDefaultState());
/*  949 */     world.setBlockState(new BlockPos(i + 10, j + 11, k + 6), Blocks.stone_stairs.getStateFromMeta(4));
/*  950 */     world.setBlockState(new BlockPos(i + 10, j + 11, k + 12), Blocks.stone_stairs.getStateFromMeta(4));
/*  951 */     world.setBlockState(new BlockPos(i + 10, j + 11, k + 15), Blocks.cobblestone.getDefaultState());
/*  952 */     world.setBlockState(new BlockPos(i + 10, j + 11, k + 16), Blocks.dirt.getDefaultState());
/*  953 */     world.setBlockState(new BlockPos(i + 10, j + 12, k + 3), Blocks.grass.getDefaultState());
/*  954 */     world.setBlockState(new BlockPos(i + 10, j + 12, k + 4), Blocks.cobblestone.getDefaultState());
/*  955 */     world.setBlockState(new BlockPos(i + 10, j + 12, k + 5), Blocks.cobblestone.getDefaultState());
/*  956 */     world.setBlockState(new BlockPos(i + 10, j + 12, k + 6), Blocks.cobblestone.getDefaultState());
/*  957 */     world.setBlockState(new BlockPos(i + 10, j + 12, k + 7), Blocks.cobblestone.getDefaultState());
/*  958 */     world.setBlockState(new BlockPos(i + 10, j + 12, k + 8), Blocks.cobblestone.getDefaultState());
/*  959 */     world.setBlockState(new BlockPos(i + 10, j + 12, k + 9), Blocks.mossy_cobblestone.getDefaultState());
/*  960 */     world.setBlockState(new BlockPos(i + 10, j + 12, k + 10), Blocks.cobblestone.getDefaultState());
/*  961 */     world.setBlockState(new BlockPos(i + 10, j + 12, k + 11), Blocks.cobblestone.getDefaultState());
/*  962 */     world.setBlockState(new BlockPos(i + 10, j + 12, k + 12), Blocks.mossy_cobblestone.getDefaultState());
/*  963 */     world.setBlockState(new BlockPos(i + 10, j + 12, k + 13), Blocks.cobblestone.getDefaultState());
/*  964 */     world.setBlockState(new BlockPos(i + 10, j + 12, k + 14), Blocks.cobblestone.getDefaultState());
/*  965 */     world.setBlockState(new BlockPos(i + 10, j + 12, k + 15), Blocks.grass.getDefaultState());
/*  966 */     world.setBlockState(new BlockPos(i + 10, j + 12, k + 16), Blocks.grass.getDefaultState());
/*  967 */     world.setBlockState(new BlockPos(i + 10, j + 13, k + 4), Blocks.grass.getDefaultState());
/*  968 */     world.setBlockState(new BlockPos(i + 10, j + 13, k + 5), Blocks.dirt.getDefaultState());
/*  969 */     world.setBlockState(new BlockPos(i + 10, j + 13, k + 6), Blocks.dirt.getDefaultState());
/*  970 */     world.setBlockState(new BlockPos(i + 10, j + 13, k + 7), Blocks.grass.getDefaultState());
/*  971 */     world.setBlockState(new BlockPos(i + 10, j + 13, k + 8), Blocks.dirt.getDefaultState());
/*  972 */     world.setBlockState(new BlockPos(i + 10, j + 13, k + 9), Blocks.dirt.getDefaultState());
/*  973 */     world.setBlockState(new BlockPos(i + 10, j + 13, k + 10), Blocks.dirt.getDefaultState());
/*  974 */     world.setBlockState(new BlockPos(i + 10, j + 13, k + 11), Blocks.dirt.getDefaultState());
